Workbook

Sheet APENDICE 4 REGISTRO DE RESULTAD
J1: FECHA REF | L1: 46022 | W1: =+A:AI -> 0
A3: EJERCITO ARGENTINO
A4: Regimiento de Caballería de Tanques 11 | U4: “Año de Reconstrucción de la Nación Argentina"
A7: REGISTRO DE RESULTADOS DE LAS PRUEBAS DE APTITUD FÍSICA BÁSICA (PAFB)
A8: Año 2025
M11: 1RA COMPROBACION - PAFB | W11: 2DA COMPROBACION - PAFB | AG11: NOTA FINAL DACA | AH11: CLASIFICACION ANUAL | AI11: TOME CONOCIMIENTO
A12: NRO | B12: GRADO | C12: ARMA / ESPECIALIDAD | D12: NOMBRE Y APELLIDO | E12: DNI | F12: FECHA NAC dd/mm/aa | G12: PESO | H12: TALLA | I12: IMC | J12: SEXO (M/F) | K12: EDAD | L12: CATEGORIA | M12: BRAZOS | O12: TRONCO / PLANCHA FRONTAL | Q12: BARRA | S12: CARRERA | U12: Promedio | V12: APROBO/ NO APROBO COMPROBACION | W12: BRAZOS | Y12: TRONCO / PLANCHA FRONTAL | AA12: BARRA | AC12: CARRERA | AE12: PROM FINAL | AF12: APROBO/ NO APROBO 2DA COMPROBACION
A13: NRO | B13: GRADO | C13: A / E / S | D13: NOMBRE/S Y APELLIDO/S | E13: DNI | F13: FECHA NAC dd/mm/aa | G13: PESO | H13: TALLA | I13: IMC | J13: SEXO (M/F) | K13: EDAD | L13: CATEGORIA | M13: Cant 1 | N13: Pts 1 | O13: Cant 2 | P13: Pts 2 | Q13: Cant 4 | R13: Pts 4 | S13: T' 5 | T13: Pts 5 | U13: Comp | V13: A / NA | W13: Cant6 | X13: Pts 6 | Y13: Cant 7 | Z13: Pts 7 | AA13: Cant 9 | AB13: Pts 9 | AC13: T' 10 | AD13: Pts 10 | AE13: 2da C | AF13: A / NA2 | AG13: DACA | AH13: A / NA3 | AI13: TOME CONOCIMIENTO | AJ13: Jerarquia
A14: 1 | I14: =IF(OR(G14="",H14=""),"-",ROUND(G14/(H14^2),0)) -> - | J14: M | K14: =IF(F14>0,DATEDIF(F14,$L$1,"Y"),"-") -> - | L14: =IF(F14="","-",IF(K14<>"",VLOOKUP(K14,T100Pts!CH$4:CI$59,(2)))) -> - | N14: =IF($L14="X","-",IF(M14="","-",IF(J14="M",VLOOKUP(M14,T100Pts!U$5:AC$86,(L14+1)),IF(J14="F",VLOOKUP(M14,T100Pts!AE$5:AM$86,(L14+1)),"")))) -> - | P14: =IF($L14="X","-",IF(O14="","-",IF(J14="M",VLOOKUP(O14,T100Pts!AO$5:AW$126,(L14+1)),IF(J14="F",VLOOKUP(O14,T100Pts!AY$5:BG$126,(L14+1)),"")))) -> - | R14: =IF(OR($L14="X",$L14=6,$L14=7),"-",IF(Q14="","-",IF(J14="M",VLOOKUP(Q14,T100Pts!BI$5:BN$44,(L14+1)),IF(J14="F",VLOOKUP(Q14,T100Pts!BU$5:BZ$44,(L14+1)),"")))) -> - | T14: =IF($L14="X","-",IF(S14="","-",IF(J14="M",VLOOKUP(S14,T100Pts!A$5:I$1146,(L14+1)),IF(J14="F",VLOOKUP(S14,T100Pts!K$5:S$1147,(L14+1)),"")))) -> - | U14: =IF(OR(N14="X",P14="X",R14="X",T14="X"),"NR",IF(AND(N14="-",P14="-",T14="-"),"-",IF(R14="-",AVERAGE(IF(ISNUMBER(N14),N14),IF(ISNUMBER(P14),P14),IF(ISNUMBER(T14),T14)),AVERAGE(IF(ISNUMBER(N14),N14),IF(ISNUMBER(P14),P14),IF(ISNUMBER(R14),R14),IF(ISNUMBER(T14),T14))))) -> - | V14: =IF(NOT(ISNUMBER(U14)), "-", IF(U14 < 70, "NA", "A")) -> - | X14: =IF($L14="X","-",IF(W14="","-",IF(J14="M",VLOOKUP(W14,T100Pts!U$5:AC$86,(L14+1)),IF(J14="F",VLOOKUP(W14,T100Pts!AE$5:AM$86,(L14+1)),"")))) -> - | Z14: =IF($L14="X","-",IF(Y14="","-",IF(J14="M",VLOOKUP(Y14,T100Pts!AO$5:AW$126,(L14+1)),IF(J14="F",VLOOKUP(Y14,T100Pts!AY$5:BG$126,(L14+1)),"")))) -> - | AB14: =IF(OR($L14="X",$L14=6,$L14=7),"-",IF(AA14="","-",IF(J14="M",VLOOKUP(AA14,T100Pts!BI$5:BN$44,(L14+1)),IF(J14="F",VLOOKUP(AA14,T100Pts!BU$5:BZ$44,(L14+1)),"")))) -> - | AD14: =IF($L14="X","-",IF(AC14="","-",IF(J14="M",VLOOKUP(AC14,T100Pts!A$5:I$1146,(L14+1)),IF(J14="F",VLOOKUP(AC14,T100Pts!K$5:S$1146,(L14+1)),"")))) -> - | AE14: =IF(OR(X14="X",Z14="X",AB14="X",AD14="X"),"NR",IF(AND(X14="-",Z14="-",AD14="-"),"-",IF(AB14="-",AVERAGE(IF(ISNUMBER(X14),X14),IF(ISNUMBER(Z14),Z14),IF(ISNUMBER(AD14),AD14)),AVERAGE(IF(ISNUMBER(X14),X14),IF(ISNUMBER(Z14),Z14),IF(ISNUMBER(AB14),AB14),IF(ISNUMBER(AD14),AD14))))) -> - | AF14: =IF(NOT(ISNUMBER(AE14)), "-", IF(AE14 < 70, "NA", "A")) -> - | AG14: =AVERAGE(U14,AE14) -> #DIV/0! | AH14: =IF(NOT(ISNUMBER(AG14)), "-", IF(AG14 < 70, "NA", "A")) -> - | AJ14: =IF(OR(B14="TG",B14="GD",B14="GB",B14="CY",B14="CR",B14="TC",B14="MY",B14="CT",B14="TP",B14="TP EC",B14="TT",B14="TT EC",B14="ST",B14="ST EC"),"Oficial",IF(OR(B14="VP",B14="VS",B14="VS EC"),"Vol",IF(B14="","","Subof")))
A15: 2 | I15: =IF(OR(G15="",H15=""),"-",ROUND(G15/(H15^2),0)) -> - | J15: M | K15: =IF(F15>0,DATEDIF(F15,$L$1,"Y"),"-") -> - | L15: =IF(F15="","-",IF(K15<>"",VLOOKUP(K15,T100Pts!CH$4:CI$59,(2)))) -> - | N15: =IF($L15="X","-",IF(M15="","-",IF(J15="M",VLOOKUP(M15,T100Pts!U$5:AC$86,(L15+1)),IF(J15="F",VLOOKUP(M15,T100Pts!AE$5:AM$86,(L15+1)),"")))) -> - | P15: =IF($L15="X","-",IF(O15="","-",IF(J15="M",VLOOKUP(O15,T100Pts!AO$5:AW$126,(L15+1)),IF(J15="F",VLOOKUP(O15,T100Pts!AY$5:BG$126,(L15+1)),"")))) -> - | R15: =IF(OR($L15="X",O16=6,$L15=7),"-",IF(Q15="","-",IF(J15="M",VLOOKUP(Q15,T100Pts!BI$5:BN$44,(L15+1)),IF(J15="F",VLOOKUP(Q15,T100Pts!BU$5:BZ$44,(L15+1)),"")))) -> - | T15: =IF($L15="X","-",IF(S15="","-",IF(J15="M",VLOOKUP(S15,T100Pts!A$5:I$1146,(L15+1)),IF(J15="F",VLOOKUP(S15,T100Pts!K$5:S$1147,(L15+1)),"")))) -> - | U15: =IF(OR(N15="X",P15="X",R15="X",T15="X"),"NR",IF(AND(N15="-",P15="-",T15="-"),"-",IF(R15="-",AVERAGE(IF(ISNUMBER(N15),N15),IF(ISNUMBER(P15),P15),IF(ISNUMBER(T15),T15)),AVERAGE(IF(ISNUMBER(N15),N15),IF(ISNUMBER(P15),P15),IF(ISNUMBER(R15),R15),IF(ISNUMBER(T15),T15))))) -> - | V15: =IF(NOT(ISNUMBER(U15)), "-", IF(U15 < 70, "NA", "A")) -> - | X15: =IF($L15="X","-",IF(W15="","-",IF(J15="M",VLOOKUP(W15,T100Pts!U$5:AC$86,(L15+1)),IF(J15="F",VLOOKUP(W15,T100Pts!AE$5:AM$86,(L15+1)),"")))) -> - | Z15: =IF($L15="X","-",IF(Y15="","-",IF(J15="M",VLOOKUP(Y15,T100Pts!AO$5:AW$126,(L15+1)),IF(J15="F",VLOOKUP(Y15,T100Pts!AY$5:BG$126,(L15+1)),"")))) -> - | AB15: =IF(OR($L15="X",$L15=6,$L15=7),"-",IF(AA15="","-",IF(J15="M",VLOOKUP(AA15,T100Pts!BI$5:BN$44,(L15+1)),IF(J15="F",VLOOKUP(AA15,T100Pts!BU$5:BZ$44,(L15+1)),"")))) -> - | AD15: =IF($L15="X","-",IF(AC15="","-",IF(J15="M",VLOOKUP(AC15,T100Pts!A$5:I$1146,(L15+1)),IF(J15="F",VLOOKUP(AC15,T100Pts!K$5:S$1146,(L15+1)),"")))) -> - | AE15: =IF(OR(X15="X",Z15="X",AB15="X",AD15="X"),"NR",IF(AND(X15="-",Z15="-",AD15="-"),"-",IF(AB15="-",AVERAGE(IF(ISNUMBER(X15),X15),IF(ISNUMBER(Z15),Z15),IF(ISNUMBER(AD15),AD15)),AVERAGE(IF(ISNUMBER(X15),X15),IF(ISNUMBER(Z15),Z15),IF(ISNUMBER(AB15),AB15),IF(ISNUMBER(AD15),AD15))))) -> - | AF15: =IF(NOT(ISNUMBER(AE15)), "-", IF(AE15 < 70, "NA", "A")) -> - | AG15: =AVERAGE(U15,AE15) -> #DIV/0! | AH15: =IF(NOT(ISNUMBER(AG15)), "-", IF(AG15 < 70, "NA", "A")) -> - | AJ15: =IF(OR(B15="TG",B15="GD",B15="GB",B15="CY",B15="CR",B15="TC",B15="MY",B15="CT",B15="TP",B15="TP EC",B15="TT",B15="TT EC",B15="ST",B15="ST EC"),"Oficial",IF(OR(B15="VP",B15="VS",B15="VS EC"),"Vol",IF(B15="","","Subof")))
A16: 3 | I16: =IF(OR(G16="",H16=""),"-",ROUND(G16/(H16^2),0)) -> - | J16: M | K16: =IF(F16>0,DATEDIF(F16,$L$1,"Y"),"-") -> - | L16: =IF(F16="","-",IF(K16<>"",VLOOKUP(K16,T100Pts!CH$4:CI$59,(2)))) -> - | N16: =IF($L16="X","-",IF(M16="","-",IF(J16="M",VLOOKUP(M16,T100Pts!U$5:AC$86,(L16+1)),IF(J16="F",VLOOKUP(M16,T100Pts!AE$5:AM$86,(L16+1)),"")))) -> - | P16: =IF($L16="X","-",IF(O16="","-",IF(J16="M",VLOOKUP(O16,T100Pts!AO$5:AW$126,(L16+1)),IF(J16="F",VLOOKUP(O16,T100Pts!AY$5:BG$126,(L16+1)),"")))) -> - | R16: =IF(OR($L16="X",$L16=6,$L16=7),"-",IF(Q16="","-",IF(J16="M",VLOOKUP(Q16,T100Pts!BI$5:BN$44,(L16+1)),IF(J16="F",VLOOKUP(Q16,T100Pts!BU$5:BZ$44,(L16+1)),"")))) -> - | T16: =IF($L16="X","-",IF(S16="","-",IF(J16="M",VLOOKUP(S16,T100Pts!A$5:I$1146,(L16+1)),IF(J16="F",VLOOKUP(S16,T100Pts!K$5:S$1147,(L16+1)),"")))) -> - | U16: =IF(OR(N16="X",P16="X",R16="X",T16="X"),"NR",IF(AND(N16="-",P16="-",T16="-"),"-",IF(R16="-",AVERAGE(IF(ISNUMBER(N16),N16),IF(ISNUMBER(P16),P16),IF(ISNUMBER(T16),T16)),AVERAGE(IF(ISNUMBER(N16),N16),IF(ISNUMBER(P16),P16),IF(ISNUMBER(R16),R16),IF(ISNUMBER(T16),T16))))) -> - | V16: =IF(NOT(ISNUMBER(U16)), "-", IF(U16 < 70, "NA", "A")) -> - | X16: =IF($L16="X","-",IF(W16="","-",IF(J16="M",VLOOKUP(W16,T100Pts!U$5:AC$86,(L16+1)),IF(J16="F",VLOOKUP(W16,T100Pts!AE$5:AM$86,(L16+1)),"")))) -> - | Z16: =IF($L16="X","-",IF(Y16="","-",IF(J16="M",VLOOKUP(Y16,T100Pts!AO$5:AW$126,(L16+1)),IF(J16="F",VLOOKUP(Y16,T100Pts!AY$5:BG$126,(L16+1)),"")))) -> - | AB16: =IF(OR($L16="X",$L16=6,$L16=7),"-",IF(AA16="","-",IF(J16="M",VLOOKUP(AA16,T100Pts!BI$5:BN$44,(L16+1)),IF(J16="F",VLOOKUP(AA16,T100Pts!BU$5:BZ$44,(L16+1)),"")))) -> - | AD16: =IF($L16="X","-",IF(AC16="","-",IF(J16="M",VLOOKUP(AC16,T100Pts!A$5:I$1146,(L16+1)),IF(J16="F",VLOOKUP(AC16,T100Pts!K$5:S$1146,(L16+1)),"")))) -> - | AE16: =IF(OR(X16="X",Z16="X",AB16="X",AD16="X"),"NR",IF(AND(X16="-",Z16="-",AD16="-"),"-",IF(AB16="-",AVERAGE(IF(ISNUMBER(X16),X16),IF(ISNUMBER(Z16),Z16),IF(ISNUMBER(AD16),AD16)),AVERAGE(IF(ISNUMBER(X16),X16),IF(ISNUMBER(Z16),Z16),IF(ISNUMBER(AB16),AB16),IF(ISNUMBER(AD16),AD16))))) -> - | AF16: =IF(NOT(ISNUMBER(AE16)), "-", IF(AE16 < 70, "NA", "A")) -> - | AG16: =AVERAGE(U16,AE16) -> #DIV/0! | AH16: =IF(NOT(ISNUMBER(AG16)), "-", IF(AG16 < 70, "NA", "A")) -> - | AJ16: =IF(OR(B16="TG",B16="GD",B16="GB",B16="CY",B16="CR",B16="TC",B16="MY",B16="CT",B16="TP",B16="TP EC",B16="TT",B16="TT EC",B16="ST",B16="ST EC"),"Oficial",IF(OR(B16="VP",B16="VS",B16="VS EC"),"Vol",IF(B16="","","Subof")))
A17: 4 | I17: =IF(OR(G17="",H17=""),"-",ROUND(G17/(H17^2),0)) -> - | J17: F | K17: =IF(F17>0,DATEDIF(F17,$L$1,"Y"),"-") -> - | L17: =IF(F17="","-",IF(K17<>"",VLOOKUP(K17,T100Pts!CH$4:CI$59,(2)))) -> - | N17: =IF($L17="X","-",IF(M17="","-",IF(J17="M",VLOOKUP(M17,T100Pts!U$5:AC$86,(L17+1)),IF(J17="F",VLOOKUP(M17,T100Pts!AE$5:AM$86,(L17+1)),"")))) -> - | P17: =IF($L17="X","-",IF(O17="","-",IF(J17="M",VLOOKUP(O17,T100Pts!AO$5:AW$126,(L17+1)),IF(J17="F",VLOOKUP(O17,T100Pts!AY$5:BG$126,(L17+1)),"")))) -> - | R17: =IF(OR($L17="X",$L17=6,$L17=7),"-",IF(Q17="","-",IF(J17="M",VLOOKUP(Q17,T100Pts!BI$5:BN$44,(L17+1)),IF(J17="F",VLOOKUP(Q17,T100Pts!BU$5:BZ$44,(L17+1)),"")))) -> - | T17: =IF($L17="X","-",IF(S17="","-",IF(J17="M",VLOOKUP(S17,T100Pts!A$5:I$1146,(L17+1)),IF(J17="F",VLOOKUP(S17,T100Pts!K$5:S$1147,(L17+1)),"")))) -> - | U17: =IF(OR(N17="X",P17="X",R17="X",T17="X"),"NR",IF(AND(N17="-",P17="-",T17="-"),"-",IF(R17="-",AVERAGE(IF(ISNUMBER(N17),N17),IF(ISNUMBER(P17),P17),IF(ISNUMBER(T17),T17)),AVERAGE(IF(ISNUMBER(N17),N17),IF(ISNUMBER(P17),P17),IF(ISNUMBER(R17),R17),IF(ISNUMBER(T17),T17))))) -> - | V17: =IF(NOT(ISNUMBER(U17)), "-", IF(U17 < 70, "NA", "A")) -> - | X17: =IF($L17="X","-",IF(W17="","-",IF(J17="M",VLOOKUP(W17,T100Pts!U$5:AC$86,(L17+1)),IF(J17="F",VLOOKUP(W17,T100Pts!AE$5:AM$86,(L17+1)),"")))) -> - | Z17: =IF($L17="X","-",IF(Y17="","-",IF(J17="M",VLOOKUP(Y17,T100Pts!AO$5:AW$126,(L17+1)),IF(J17="F",VLOOKUP(Y17,T100Pts!AY$5:BG$126,(L17+1)),"")))) -> - | AB17: =IF(OR($L17="X",$L17=6,$L17=7),"-",IF(AA17="","-",IF(J17="M",VLOOKUP(AA17,T100Pts!BI$5:BN$44,(L17+1)),IF(J17="F",VLOOKUP(AA17,T100Pts!BU$5:BZ$44,(L17+1)),"")))) -> - | AD17: =IF($L17="X","-",IF(AC17="","-",IF(J17="M",VLOOKUP(AC17,T100Pts!A$5:I$1146,(L17+1)),IF(J17="F",VLOOKUP(AC17,T100Pts!K$5:S$1146,(L17+1)),"")))) -> - | AE17: =IF(OR(X17="X",Z17="X",AB17="X",AD17="X"),"NR",IF(AND(X17="-",Z17="-",AD17="-"),"-",IF(AB17="-",AVERAGE(IF(ISNUMBER(X17),X17),IF(ISNUMBER(Z17),Z17),IF(ISNUMBER(AD17),AD17)),AVERAGE(IF(ISNUMBER(X17),X17),IF(ISNUMBER(Z17),Z17),IF(ISNUMBER(AB17),AB17),IF(ISNUMBER(AD17),AD17))))) -> - | AF17: =IF(NOT(ISNUMBER(AE17)), "-", IF(AE17 < 70, "NA", "A")) -> - | AG17: =AVERAGE(U17,AE17) -> #DIV/0! | AH17: =IF(NOT(ISNUMBER(AG17)), "-", IF(AG17 < 70, "NA", "A")) -> - | AI17: APTO B | AJ17: =IF(OR(B17="TG",B17="GD",B17="GB",B17="CY",B17="CR",B17="TC",B17="MY",B17="CT",B17="TP",B17="TP EC",B17="TT",B17="TT EC",B17="ST",B17="ST EC"),"Oficial",IF(OR(B17="VP",B17="VS",B17="VS EC"),"Vol",IF(B17="","","Subof")))
A18: 5 | I18: =IF(OR(G18="",H18=""),"-",ROUND(G18/(H18^2),0)) -> - | J18: M | K18: =IF(F18>0,DATEDIF(F18,$L$1,"Y"),"-") -> - | L18: =IF(F18="","-",IF(K18<>"",VLOOKUP(K18,T100Pts!CH$4:CI$59,(2)))) -> - | N18: =IF($L18="X","-",IF(M18="","-",IF(J18="M",VLOOKUP(M18,T100Pts!U$5:AC$86,(L18+1)),IF(J18="F",VLOOKUP(M18,T100Pts!AE$5:AM$86,(L18+1)),"")))) -> - | P18: =IF($L18="X","-",IF(O18="","-",IF(J18="M",VLOOKUP(O18,T100Pts!AO$5:AW$126,(L18+1)),IF(J18="F",VLOOKUP(O18,T100Pts!AY$5:BG$126,(L18+1)),"")))) -> - | R18: =IF(OR($L18="X",$L18=6,$L18=7),"-",IF(Q18="","-",IF(J18="M",VLOOKUP(Q18,T100Pts!BI$5:BN$44,(L18+1)),IF(J18="F",VLOOKUP(Q18,T100Pts!BU$5:BZ$44,(L18+1)),"")))) -> - | T18: =IF($L18="X","-",IF(S18="","-",IF(J18="M",VLOOKUP(S18,T100Pts!A$5:I$1146,(L18+1)),IF(J18="F",VLOOKUP(S18,T100Pts!K$5:S$1147,(L18+1)),"")))) -> - | U18: =IF(OR(N18="X",P18="X",R18="X",T18="X"),"NR",IF(AND(N18="-",P18="-",T18="-"),"-",IF(R18="-",AVERAGE(IF(ISNUMBER(N18),N18),IF(ISNUMBER(P18),P18),IF(ISNUMBER(T18),T18)),AVERAGE(IF(ISNUMBER(N18),N18),IF(ISNUMBER(P18),P18),IF(ISNUMBER(R18),R18),IF(ISNUMBER(T18),T18))))) -> - | V18: =IF(NOT(ISNUMBER(U18)), "-", IF(U18 < 70, "NA", "A")) -> - | X18: =IF($L18="X","-",IF(W18="","-",IF(J18="M",VLOOKUP(W18,T100Pts!U$5:AC$86,(L18+1)),IF(J18="F",VLOOKUP(W18,T100Pts!AE$5:AM$86,(L18+1)),"")))) -> - | Z18: =IF($L18="X","-",IF(Y18="","-",IF(J18="M",VLOOKUP(Y18,T100Pts!AO$5:AW$126,(L18+1)),IF(J18="F",VLOOKUP(Y18,T100Pts!AY$5:BG$126,(L18+1)),"")))) -> - | AB18: =IF(OR($L18="X",$L18=6,$L18=7),"-",IF(AA18="","-",IF(J18="M",VLOOKUP(AA18,T100Pts!BI$5:BN$44,(L18+1)),IF(J18="F",VLOOKUP(AA18,T100Pts!BU$5:BZ$44,(L18+1)),"")))) -> - | AD18: =IF($L18="X","-",IF(AC18="","-",IF(J18="M",VLOOKUP(AC18,T100Pts!A$5:I$1146,(L18+1)),IF(J18="F",VLOOKUP(AC18,T100Pts!K$5:S$1146,(L18+1)),"")))) -> - | AE18: =IF(OR(X18="X",Z18="X",AB18="X",AD18="X"),"NR",IF(AND(X18="-",Z18="-",AD18="-"),"-",IF(AB18="-",AVERAGE(IF(ISNUMBER(X18),X18),IF(ISNUMBER(Z18),Z18),IF(ISNUMBER(AD18),AD18)),AVERAGE(IF(ISNUMBER(X18),X18),IF(ISNUMBER(Z18),Z18),IF(ISNUMBER(AB18),AB18),IF(ISNUMBER(AD18),AD18))))) -> - | AF18: =IF(NOT(ISNUMBER(AE18)), "-", IF(AE18 < 70, "NA", "A")) -> - | AG18: =AVERAGE(U18,AE18) -> #DIV/0! | AH18: =IF(NOT(ISNUMBER(AG18)), "-", IF(AG18 < 70, "NA", "A")) -> - | AJ18: =IF(OR(B18="TG",B18="GD",B18="GB",B18="CY",B18="CR",B18="TC",B18="MY",B18="CT",B18="TP",B18="TP EC",B18="TT",B18="TT EC",B18="ST",B18="ST EC"),"Oficial",IF(OR(B18="VP",B18="VS",B18="VS EC"),"Vol",IF(B18="","","Subof")))
A19: 6 | I19: =IF(OR(G19="",H19=""),"-",ROUND(G19/(H19^2),0)) -> - | J19: M | K19: =IF(F19>0,DATEDIF(F19,$L$1,"Y"),"-") -> - | L19: =IF(F19="","-",IF(K19<>"",VLOOKUP(K19,T100Pts!CH$4:CI$59,(2)))) -> - | N19: =IF($L19="X","-",IF(M19="","-",IF(J19="M",VLOOKUP(M19,T100Pts!U$5:AC$86,(L19+1)),IF(J19="F",VLOOKUP(M19,T100Pts!AE$5:AM$86,(L19+1)),"")))) -> - | P19: =IF($L19="X","-",IF(O19="","-",IF(J19="M",VLOOKUP(O19,T100Pts!AO$5:AW$126,(L19+1)),IF(J19="F",VLOOKUP(O19,T100Pts!AY$5:BG$126,(L19+1)),"")))) -> - | R19: =IF(OR($L19="X",$L19=6,$L19=7),"-",IF(Q19="","-",IF(J19="M",VLOOKUP(Q19,T100Pts!BI$5:BN$44,(L19+1)),IF(J19="F",VLOOKUP(Q19,T100Pts!BU$5:BZ$44,(L19+1)),"")))) -> - | T19: =IF($L19="X","-",IF(S19="","-",IF(J19="M",VLOOKUP(S19,T100Pts!A$5:I$1146,(L19+1)),IF(J19="F",VLOOKUP(S19,T100Pts!K$5:S$1147,(L19+1)),"")))) -> - | U19: =IF(OR(N19="X",P19="X",R19="X",T19="X"),"NR",IF(AND(N19="-",P19="-",T19="-"),"-",IF(R19="-",AVERAGE(IF(ISNUMBER(N19),N19),IF(ISNUMBER(P19),P19),IF(ISNUMBER(T19),T19)),AVERAGE(IF(ISNUMBER(N19),N19),IF(ISNUMBER(P19),P19),IF(ISNUMBER(R19),R19),IF(ISNUMBER(T19),T19))))) -> - | V19: =IF(NOT(ISNUMBER(U19)), "-", IF(U19 < 70, "NA", "A")) -> - | X19: =IF($L19="X","-",IF(W19="","-",IF(J19="M",VLOOKUP(W19,T100Pts!U$5:AC$86,(L19+1)),IF(J19="F",VLOOKUP(W19,T100Pts!AE$5:AM$86,(L19+1)),"")))) -> - | Z19: =IF($L19="X","-",IF(Y19="","-",IF(J19="M",VLOOKUP(Y19,T100Pts!AO$5:AW$126,(L19+1)),IF(J19="F",VLOOKUP(Y19,T100Pts!AY$5:BG$126,(L19+1)),"")))) -> - | AB19: =IF(OR($L19="X",$L19=6,$L19=7),"-",IF(AA19="","-",IF(J19="M",VLOOKUP(AA19,T100Pts!BI$5:BN$44,(L19+1)),IF(J19="F",VLOOKUP(AA19,T100Pts!BU$5:BZ$44,(L19+1)),"")))) -> - | AD19: =IF($L19="X","-",IF(AC19="","-",IF(J19="M",VLOOKUP(AC19,T100Pts!A$5:I$1146,(L19+1)),IF(J19="F",VLOOKUP(AC19,T100Pts!K$5:S$1146,(L19+1)),"")))) -> - | AE19: =IF(OR(X19="X",Z19="X",AB19="X",AD19="X"),"NR",IF(AND(X19="-",Z19="-",AD19="-"),"-",IF(AB19="-",AVERAGE(IF(ISNUMBER(X19),X19),IF(ISNUMBER(Z19),Z19),IF(ISNUMBER(AD19),AD19)),AVERAGE(IF(ISNUMBER(X19),X19),IF(ISNUMBER(Z19),Z19),IF(ISNUMBER(AB19),AB19),IF(ISNUMBER(AD19),AD19))))) -> - | AF19: =IF(NOT(ISNUMBER(AE19)), "-", IF(AE19 < 70, "NA", "A")) -> - | AG19: =AVERAGE(U19,AE19) -> #DIV/0! | AH19: =IF(NOT(ISNUMBER(AG19)), "-", IF(AG19 < 70, "NA", "A")) -> - | AJ19: =IF(OR(B19="TG",B19="GD",B19="GB",B19="CY",B19="CR",B19="TC",B19="MY",B19="CT",B19="TP",B19="TP EC",B19="TT",B19="TT EC",B19="ST",B19="ST EC"),"Oficial",IF(OR(B19="VP",B19="VS",B19="VS EC"),"Vol",IF(B19="","","Subof")))
A20: 7 | I20: =IF(OR(G20="",H20=""),"-",ROUND(G20/(H20^2),0)) -> - | J20: M | K20: =IF(F20>0,DATEDIF(F20,$L$1,"Y"),"-") -> - | L20: =IF(F20="","-",IF(K20<>"",VLOOKUP(K20,T100Pts!CH$4:CI$59,(2)))) -> - | N20: =IF($L20="X","-",IF(M20="","-",IF(J20="M",VLOOKUP(M20,T100Pts!U$5:AC$86,(L20+1)),IF(J20="F",VLOOKUP(M20,T100Pts!AE$5:AM$86,(L20+1)),"")))) -> - | P20: =IF($L20="X","-",IF(O20="","-",IF(J20="M",VLOOKUP(O20,T100Pts!AO$5:AW$126,(L20+1)),IF(J20="F",VLOOKUP(O20,T100Pts!AY$5:BG$126,(L20+1)),"")))) -> - | R20: =IF(OR($L20="X",$L20=6,$L20=7),"-",IF(Q20="","-",IF(J20="M",VLOOKUP(Q20,T100Pts!BI$5:BN$44,(L20+1)),IF(J20="F",VLOOKUP(Q20,T100Pts!BU$5:BZ$44,(L20+1)),"")))) -> - | T20: =IF($L20="X","-",IF(S20="","-",IF(J20="M",VLOOKUP(S20,T100Pts!A$5:I$1146,(L20+1)),IF(J20="F",VLOOKUP(S20,T100Pts!K$5:S$1147,(L20+1)),"")))) -> - | U20: =IF(OR(N20="X",P20="X",R20="X",T20="X"),"NR",IF(AND(N20="-",P20="-",T20="-"),"-",IF(R20="-",AVERAGE(IF(ISNUMBER(N20),N20),IF(ISNUMBER(P20),P20),IF(ISNUMBER(T20),T20)),AVERAGE(IF(ISNUMBER(N20),N20),IF(ISNUMBER(P20),P20),IF(ISNUMBER(R20),R20),IF(ISNUMBER(T20),T20))))) -> - | V20: =IF(NOT(ISNUMBER(U20)), "-", IF(U20 < 70, "NA", "A")) -> - | X20: =IF($L20="X","-",IF(W20="","-",IF(J20="M",VLOOKUP(W20,T100Pts!U$5:AC$86,(L20+1)),IF(J20="F",VLOOKUP(W20,T100Pts!AE$5:AM$86,(L20+1)),"")))) -> - | Z20: =IF($L20="X","-",IF(Y20="","-",IF(J20="M",VLOOKUP(Y20,T100Pts!AO$5:AW$126,(L20+1)),IF(J20="F",VLOOKUP(Y20,T100Pts!AY$5:BG$126,(L20+1)),"")))) -> - | AB20: =IF(OR($L20="X",$L20=6,$L20=7),"-",IF(AA20="","-",IF(J20="M",VLOOKUP(AA20,T100Pts!BI$5:BN$44,(L20+1)),IF(J20="F",VLOOKUP(AA20,T100Pts!BU$5:BZ$44,(L20+1)),"")))) -> - | AD20: =IF($L20="X","-",IF(AC20="","-",IF(J20="M",VLOOKUP(AC20,T100Pts!A$5:I$1146,(L20+1)),IF(J20="F",VLOOKUP(AC20,T100Pts!K$5:S$1146,(L20+1)),"")))) -> - | AE20: =IF(OR(X20="X",Z20="X",AB20="X",AD20="X"),"NR",IF(AND(X20="-",Z20="-",AD20="-"),"-",IF(AB20="-",AVERAGE(IF(ISNUMBER(X20),X20),IF(ISNUMBER(Z20),Z20),IF(ISNUMBER(AD20),AD20)),AVERAGE(IF(ISNUMBER(X20),X20),IF(ISNUMBER(Z20),Z20),IF(ISNUMBER(AB20),AB20),IF(ISNUMBER(AD20),AD20))))) -> - | AF20: =IF(NOT(ISNUMBER(AE20)), "-", IF(AE20 < 70, "NA", "A")) -> - | AG20: =AVERAGE(U20,AE20) -> #DIV/0! | AH20: =IF(NOT(ISNUMBER(AG20)), "-", IF(AG20 < 70, "NA", "A")) -> - | AJ20: =IF(OR(B20="TG",B20="GD",B20="GB",B20="CY",B20="CR",B20="TC",B20="MY",B20="CT",B20="TP",B20="TP EC",B20="TT",B20="TT EC",B20="ST",B20="ST EC"),"Oficial",IF(OR(B20="VP",B20="VS",B20="VS EC"),"Vol",IF(B20="","","Subof")))
A21: 8 | I21: =IF(OR(G21="",H21=""),"-",ROUND(G21/(H21^2),0)) -> - | J21: M | K21: =IF(F21>0,DATEDIF(F21,$L$1,"Y"),"-") -> - | L21: =IF(F21="","-",IF(K21<>"",VLOOKUP(K21,T100Pts!CH$4:CI$59,(2)))) -> - | N21: =IF($L21="X","-",IF(M21="","-",IF(J21="M",VLOOKUP(M21,T100Pts!U$5:AC$86,(L21+1)),IF(J21="F",VLOOKUP(M21,T100Pts!AE$5:AM$86,(L21+1)),"")))) -> - | P21: =IF($L21="X","-",IF(O21="","-",IF(J21="M",VLOOKUP(O21,T100Pts!AO$5:AW$126,(L21+1)),IF(J21="F",VLOOKUP(O21,T100Pts!AY$5:BG$126,(L21+1)),"")))) -> - | R21: =IF(OR($L21="X",$L21=6,$L21=7),"-",IF(Q21="","-",IF(J21="M",VLOOKUP(Q21,T100Pts!BI$5:BN$44,(L21+1)),IF(J21="F",VLOOKUP(Q21,T100Pts!BU$5:BZ$44,(L21+1)),"")))) -> - | T21: =IF($L21="X","-",IF(S21="","-",IF(J21="M",VLOOKUP(S21,T100Pts!A$5:I$1146,(L21+1)),IF(J21="F",VLOOKUP(S21,T100Pts!K$5:S$1147,(L21+1)),"")))) -> - | U21: =IF(OR(N21="X",P21="X",R21="X",T21="X"),"NR",IF(AND(N21="-",P21="-",T21="-"),"-",IF(R21="-",AVERAGE(IF(ISNUMBER(N21),N21),IF(ISNUMBER(P21),P21),IF(ISNUMBER(T21),T21)),AVERAGE(IF(ISNUMBER(N21),N21),IF(ISNUMBER(P21),P21),IF(ISNUMBER(R21),R21),IF(ISNUMBER(T21),T21))))) -> - | V21: =IF(NOT(ISNUMBER(U21)), "-", IF(U21 < 70, "NA", "A")) -> - | X21: =IF($L21="X","-",IF(W21="","-",IF(J21="M",VLOOKUP(W21,T100Pts!U$5:AC$86,(L21+1)),IF(J21="F",VLOOKUP(W21,T100Pts!AE$5:AM$86,(L21+1)),"")))) -> - | Z21: =IF($L21="X","-",IF(Y21="","-",IF(J21="M",VLOOKUP(Y21,T100Pts!AO$5:AW$126,(L21+1)),IF(J21="F",VLOOKUP(Y21,T100Pts!AY$5:BG$126,(L21+1)),"")))) -> - | AB21: =IF(OR($L21="X",$L21=6,$L21=7),"-",IF(AA21="","-",IF(J21="M",VLOOKUP(AA21,T100Pts!BI$5:BN$44,(L21+1)),IF(J21="F",VLOOKUP(AA21,T100Pts!BU$5:BZ$44,(L21+1)),"")))) -> - | AD21: =IF($L21="X","-",IF(AC21="","-",IF(J21="M",VLOOKUP(AC21,T100Pts!A$5:I$1146,(L21+1)),IF(J21="F",VLOOKUP(AC21,T100Pts!K$5:S$1146,(L21+1)),"")))) -> - | AE21: =IF(OR(X21="X",Z21="X",AB21="X",AD21="X"),"NR",IF(AND(X21="-",Z21="-",AD21="-"),"-",IF(AB21="-",AVERAGE(IF(ISNUMBER(X21),X21),IF(ISNUMBER(Z21),Z21),IF(ISNUMBER(AD21),AD21)),AVERAGE(IF(ISNUMBER(X21),X21),IF(ISNUMBER(Z21),Z21),IF(ISNUMBER(AB21),AB21),IF(ISNUMBER(AD21),AD21))))) -> - | AF21: =IF(NOT(ISNUMBER(AE21)), "-", IF(AE21 < 70, "NA", "A")) -> - | AG21: =AVERAGE(U21,AE21) -> #DIV/0! | AH21: =IF(NOT(ISNUMBER(AG21)), "-", IF(AG21 < 70, "NA", "A")) -> - | AI21: PARTE DE ENF CIE: M25,6 | AJ21: =IF(OR(B21="TG",B21="GD",B21="GB",B21="CY",B21="CR",B21="TC",B21="MY",B21="CT",B21="TP",B21="TP EC",B21="TT",B21="TT EC",B21="ST",B21="ST EC"),"Oficial",IF(OR(B21="VP",B21="VS",B21="VS EC"),"Vol",IF(B21="","","Subof")))
A22: 9 | I22: =IF(OR(G22="",H22=""),"-",ROUND(G22/(H22^2),0)) -> - | J22: M | K22: =IF(F22>0,DATEDIF(F22,$L$1,"Y"),"-") -> - | L22: =IF(F22="","-",IF(K22<>"",VLOOKUP(K22,T100Pts!CH$4:CI$59,(2)))) -> - | N22: =IF($L22="X","-",IF(M22="","-",IF(J22="M",VLOOKUP(M22,T100Pts!U$5:AC$86,(L22+1)),IF(J22="F",VLOOKUP(M22,T100Pts!AE$5:AM$86,(L22+1)),"")))) -> - | P22: =IF($L22="X","-",IF(O22="","-",IF(J22="M",VLOOKUP(O22,T100Pts!AO$5:AW$126,(L22+1)),IF(J22="F",VLOOKUP(O22,T100Pts!AY$5:BG$126,(L22+1)),"")))) -> - | R22: =IF(OR($L22="X",$L22=6,$L22=7),"-",IF(Q22="","-",IF(J22="M",VLOOKUP(Q22,T100Pts!BI$5:BN$44,(L22+1)),IF(J22="F",VLOOKUP(Q22,T100Pts!BU$5:BZ$44,(L22+1)),"")))) -> - | T22: =IF($L22="X","-",IF(S22="","-",IF(J22="M",VLOOKUP(S22,T100Pts!A$5:I$1146,(L22+1)),IF(J22="F",VLOOKUP(S22,T100Pts!K$5:S$1147,(L22+1)),"")))) -> - | U22: =IF(OR(N22="X",P22="X",R22="X",T22="X"),"NR",IF(AND(N22="-",P22="-",T22="-"),"-",IF(R22="-",AVERAGE(IF(ISNUMBER(N22),N22),IF(ISNUMBER(P22),P22),IF(ISNUMBER(T22),T22)),AVERAGE(IF(ISNUMBER(N22),N22),IF(ISNUMBER(P22),P22),IF(ISNUMBER(R22),R22),IF(ISNUMBER(T22),T22))))) -> - | V22: =IF(NOT(ISNUMBER(U22)), "-", IF(U22 < 70, "NA", "A")) -> - | X22: =IF($L22="X","-",IF(W22="","-",IF(J22="M",VLOOKUP(W22,T100Pts!U$5:AC$86,(L22+1)),IF(J22="F",VLOOKUP(W22,T100Pts!AE$5:AM$86,(L22+1)),"")))) -> - | Z22: =IF($L22="X","-",IF(Y22="","-",IF(J22="M",VLOOKUP(Y22,T100Pts!AO$5:AW$126,(L22+1)),IF(J22="F",VLOOKUP(Y22,T100Pts!AY$5:BG$126,(L22+1)),"")))) -> - | AB22: =IF(OR($L22="X",$L22=6,$L22=7),"-",IF(AA22="","-",IF(J22="M",VLOOKUP(AA22,T100Pts!BI$5:BN$44,(L22+1)),IF(J22="F",VLOOKUP(AA22,T100Pts!BU$5:BZ$44,(L22+1)),"")))) -> - | AD22: =IF($L22="X","-",IF(AC22="","-",IF(J22="M",VLOOKUP(AC22,T100Pts!A$5:I$1146,(L22+1)),IF(J22="F",VLOOKUP(AC22,T100Pts!K$5:S$1146,(L22+1)),"")))) -> - | AE22: =IF(OR(X22="X",Z22="X",AB22="X",AD22="X"),"NR",IF(AND(X22="-",Z22="-",AD22="-"),"-",IF(AB22="-",AVERAGE(IF(ISNUMBER(X22),X22),IF(ISNUMBER(Z22),Z22),IF(ISNUMBER(AD22),AD22)),AVERAGE(IF(ISNUMBER(X22),X22),IF(ISNUMBER(Z22),Z22),IF(ISNUMBER(AB22),AB22),IF(ISNUMBER(AD22),AD22))))) -> - | AF22: =IF(NOT(ISNUMBER(AE22)), "-", IF(AE22 < 70, "NA", "A")) -> - | AG22: =AVERAGE(U22,AE22) -> #DIV/0! | AH22: =IF(NOT(ISNUMBER(AG22)), "-", IF(AG22 < 70, "NA", "A")) -> - | AJ22: =IF(OR(B22="TG",B22="GD",B22="GB",B22="CY",B22="CR",B22="TC",B22="MY",B22="CT",B22="TP",B22="TP EC",B22="TT",B22="TT EC",B22="ST",B22="ST EC"),"Oficial",IF(OR(B22="VP",B22="VS",B22="VS EC"),"Vol",IF(B22="","","Subof")))
A23: 10 | I23: =IF(OR(G23="",H23=""),"-",ROUND(G23/(H23^2),0)) -> - | J23: F | K23: =IF(F23>0,DATEDIF(F23,$L$1,"Y"),"-") -> - | L23: =IF(F23="","-",IF(K23<>"",VLOOKUP(K23,T100Pts!CH$4:CI$59,(2)))) -> - | N23: =IF($L23="X","-",IF(M23="","-",IF(J23="M",VLOOKUP(M23,T100Pts!U$5:AC$86,(L23+1)),IF(J23="F",VLOOKUP(M23,T100Pts!AE$5:AM$86,(L23+1)),"")))) -> - | P23: =IF($L23="X","-",IF(O23="","-",IF(J23="M",VLOOKUP(O23,T100Pts!AO$5:AW$126,(L23+1)),IF(J23="F",VLOOKUP(O23,T100Pts!AY$5:BG$126,(L23+1)),"")))) -> - | R23: =IF(OR($L23="X",$L23=6,$L23=7),"-",IF(Q23="","-",IF(J23="M",VLOOKUP(Q23,T100Pts!BI$5:BN$44,(L23+1)),IF(J23="F",VLOOKUP(Q23,T100Pts!BU$5:BZ$44,(L23+1)),"")))) -> - | T23: =IF($L23="X","-",IF(S23="","-",IF(J23="M",VLOOKUP(S23,T100Pts!A$5:I$1146,(L23+1)),IF(J23="F",VLOOKUP(S23,T100Pts!K$5:S$1147,(L23+1)),"")))) -> - | U23: =IF(OR(N23="X",P23="X",R23="X",T23="X"),"NR",IF(AND(N23="-",P23="-",T23="-"),"-",IF(R23="-",AVERAGE(IF(ISNUMBER(N23),N23),IF(ISNUMBER(P23),P23),IF(ISNUMBER(T23),T23)),AVERAGE(IF(ISNUMBER(N23),N23),IF(ISNUMBER(P23),P23),IF(ISNUMBER(R23),R23),IF(ISNUMBER(T23),T23))))) -> - | V23: =IF(NOT(ISNUMBER(U23)), "-", IF(U23 < 70, "NA", "A")) -> - | X23: =IF($L23="X","-",IF(W23="","-",IF(J23="M",VLOOKUP(W23,T100Pts!U$5:AC$86,(L23+1)),IF(J23="F",VLOOKUP(W23,T100Pts!AE$5:AM$86,(L23+1)),"")))) -> - | Z23: =IF($L23="X","-",IF(Y23="","-",IF(J23="M",VLOOKUP(Y23,T100Pts!AO$5:AW$126,(L23+1)),IF(J23="F",VLOOKUP(Y23,T100Pts!AY$5:BG$126,(L23+1)),"")))) -> - | AB23: =IF(OR($L23="X",$L23=6,$L23=7),"-",IF(AA23="","-",IF(J23="M",VLOOKUP(AA23,T100Pts!BI$5:BN$44,(L23+1)),IF(J23="F",VLOOKUP(AA23,T100Pts!BU$5:BZ$44,(L23+1)),"")))) -> - | AD23: =IF($L23="X","-",IF(AC23="","-",IF(J23="M",VLOOKUP(AC23,T100Pts!A$5:I$1146,(L23+1)),IF(J23="F",VLOOKUP(AC23,T100Pts!K$5:S$1146,(L23+1)),"")))) -> - | AE23: =IF(OR(X23="X",Z23="X",AB23="X",AD23="X"),"NR",IF(AND(X23="-",Z23="-",AD23="-"),"-",IF(AB23="-",AVERAGE(IF(ISNUMBER(X23),X23),IF(ISNUMBER(Z23),Z23),IF(ISNUMBER(AD23),AD23)),AVERAGE(IF(ISNUMBER(X23),X23),IF(ISNUMBER(Z23),Z23),IF(ISNUMBER(AB23),AB23),IF(ISNUMBER(AD23),AD23))))) -> - | AF23: =IF(NOT(ISNUMBER(AE23)), "-", IF(AE23 < 70, "NA", "A")) -> - | AG23: =AVERAGE(U23,AE23) -> #DIV/0! | AH23: =IF(NOT(ISNUMBER(AG23)), "-", IF(AG23 < 70, "NA", "A")) -> - | AJ23: =IF(OR(B23="TG",B23="GD",B23="GB",B23="CY",B23="CR",B23="TC",B23="MY",B23="CT",B23="TP",B23="TP EC",B23="TT",B23="TT EC",B23="ST",B23="ST EC"),"Oficial",IF(OR(B23="VP",B23="VS",B23="VS EC"),"Vol",IF(B23="","","Subof")))
A24: 11 | I24: =IF(OR(G24="",H24=""),"-",ROUND(G24/(H24^2),0)) -> - | J24: M | K24: =IF(F24>0,DATEDIF(F24,$L$1,"Y"),"-") -> - | L24: =IF(F24="","-",IF(K24<>"",VLOOKUP(K24,T100Pts!CH$4:CI$59,(2)))) -> - | N24: =IF($L24="X","-",IF(M24="","-",IF(J24="M",VLOOKUP(M24,T100Pts!U$5:AC$86,(L24+1)),IF(J24="F",VLOOKUP(M24,T100Pts!AE$5:AM$86,(L24+1)),"")))) -> - | P24: =IF($L24="X","-",IF(O24="","-",IF(J24="M",VLOOKUP(O24,T100Pts!AO$5:AW$126,(L24+1)),IF(J24="F",VLOOKUP(O24,T100Pts!AY$5:BG$126,(L24+1)),"")))) -> - | R24: =IF(OR($L24="X",$L24=6,$L24=7),"-",IF(Q24="","-",IF(J24="M",VLOOKUP(Q24,T100Pts!BI$5:BN$44,(L24+1)),IF(J24="F",VLOOKUP(Q24,T100Pts!BU$5:BZ$44,(L24+1)),"")))) -> - | T24: =IF($L24="X","-",IF(S24="","-",IF(J24="M",VLOOKUP(S24,T100Pts!A$5:I$1146,(L24+1)),IF(J24="F",VLOOKUP(S24,T100Pts!K$5:S$1147,(L24+1)),"")))) -> - | U24: =IF(OR(N24="X",P24="X",R24="X",T24="X"),"NR",IF(AND(N24="-",P24="-",T24="-"),"-",IF(R24="-",AVERAGE(IF(ISNUMBER(N24),N24),IF(ISNUMBER(P24),P24),IF(ISNUMBER(T24),T24)),AVERAGE(IF(ISNUMBER(N24),N24),IF(ISNUMBER(P24),P24),IF(ISNUMBER(R24),R24),IF(ISNUMBER(T24),T24))))) -> - | V24: =IF(NOT(ISNUMBER(U24)), "-", IF(U24 < 70, "NA", "A")) -> - | X24: =IF($L24="X","-",IF(W24="","-",IF(J24="M",VLOOKUP(W24,T100Pts!U$5:AC$86,(L24+1)),IF(J24="F",VLOOKUP(W24,T100Pts!AE$5:AM$86,(L24+1)),"")))) -> - | Z24: =IF($L24="X","-",IF(Y24="","-",IF(J24="M",VLOOKUP(Y24,T100Pts!AO$5:AW$126,(L24+1)),IF(J24="F",VLOOKUP(Y24,T100Pts!AY$5:BG$126,(L24+1)),"")))) -> - | AB24: =IF(OR($L24="X",$L24=6,$L24=7),"-",IF(AA24="","-",IF(J24="M",VLOOKUP(AA24,T100Pts!BI$5:BN$44,(L24+1)),IF(J24="F",VLOOKUP(AA24,T100Pts!BU$5:BZ$44,(L24+1)),"")))) -> - | AD24: =IF($L24="X","-",IF(AC24="","-",IF(J24="M",VLOOKUP(AC24,T100Pts!A$5:I$1146,(L24+1)),IF(J24="F",VLOOKUP(AC24,T100Pts!K$5:S$1146,(L24+1)),"")))) -> - | AE24: =IF(OR(X24="X",Z24="X",AB24="X",AD24="X"),"NR",IF(AND(X24="-",Z24="-",AD24="-"),"-",IF(AB24="-",AVERAGE(IF(ISNUMBER(X24),X24),IF(ISNUMBER(Z24),Z24),IF(ISNUMBER(AD24),AD24)),AVERAGE(IF(ISNUMBER(X24),X24),IF(ISNUMBER(Z24),Z24),IF(ISNUMBER(AB24),AB24),IF(ISNUMBER(AD24),AD24))))) -> - | AF24: =IF(NOT(ISNUMBER(AE24)), "-", IF(AE24 < 70, "NA", "A")) -> - | AG24: =AVERAGE(U24,AE24) -> #DIV/0! | AH24: =IF(NOT(ISNUMBER(AG24)), "-", IF(AG24 < 70, "NA", "A")) -> - | AJ24: =IF(OR(B24="TG",B24="GD",B24="GB",B24="CY",B24="CR",B24="TC",B24="MY",B24="CT",B24="TP",B24="TP EC",B24="TT",B24="TT EC",B24="ST",B24="ST EC"),"Oficial",IF(OR(B24="VP",B24="VS",B24="VS EC"),"Vol",IF(B24="","","Subof")))
A25: 12 | I25: =IF(OR(G25="",H25=""),"-",ROUND(G25/(H25^2),0)) -> - | J25: M | K25: =IF(F25>0,DATEDIF(F25,$L$1,"Y"),"-") -> - | L25: =IF(F25="","-",IF(K25<>"",VLOOKUP(K25,T100Pts!CH$4:CI$59,(2)))) -> - | N25: =IF($L25="X","-",IF(M25="","-",IF(J25="M",VLOOKUP(M25,T100Pts!U$5:AC$86,(L25+1)),IF(J25="F",VLOOKUP(M25,T100Pts!AE$5:AM$86,(L25+1)),"")))) -> - | P25: =IF($L25="X","-",IF(O25="","-",IF(J25="M",VLOOKUP(O25,T100Pts!AO$5:AW$126,(L25+1)),IF(J25="F",VLOOKUP(O25,T100Pts!AY$5:BG$126,(L25+1)),"")))) -> - | R25: =IF(OR($L25="X",$L25=6,$L25=7),"-",IF(Q25="","-",IF(J25="M",VLOOKUP(Q25,T100Pts!BI$5:BN$44,(L25+1)),IF(J25="F",VLOOKUP(Q25,T100Pts!BU$5:BZ$44,(L25+1)),"")))) -> - | T25: =IF($L25="X","-",IF(S25="","-",IF(J25="M",VLOOKUP(S25,T100Pts!A$5:I$1146,(L25+1)),IF(J25="F",VLOOKUP(S25,T100Pts!K$5:S$1147,(L25+1)),"")))) -> - | U25: =IF(OR(N25="X",P25="X",R25="X",T25="X"),"NR",IF(AND(N25="-",P25="-",T25="-"),"-",IF(R25="-",AVERAGE(IF(ISNUMBER(N25),N25),IF(ISNUMBER(P25),P25),IF(ISNUMBER(T25),T25)),AVERAGE(IF(ISNUMBER(N25),N25),IF(ISNUMBER(P25),P25),IF(ISNUMBER(R25),R25),IF(ISNUMBER(T25),T25))))) -> - | V25: =IF(NOT(ISNUMBER(U25)), "-", IF(U25 < 70, "NA", "A")) -> - | X25: =IF($L25="X","-",IF(W25="","-",IF(J25="M",VLOOKUP(W25,T100Pts!U$5:AC$86,(L25+1)),IF(J25="F",VLOOKUP(W25,T100Pts!AE$5:AM$86,(L25+1)),"")))) -> - | Z25: =IF($L25="X","-",IF(Y25="","-",IF(J25="M",VLOOKUP(Y25,T100Pts!AO$5:AW$126,(L25+1)),IF(J25="F",VLOOKUP(Y25,T100Pts!AY$5:BG$126,(L25+1)),"")))) -> - | AB25: =IF(OR($L25="X",$L25=6,$L25=7),"-",IF(AA25="","-",IF(J25="M",VLOOKUP(AA25,T100Pts!BI$5:BN$44,(L25+1)),IF(J25="F",VLOOKUP(AA25,T100Pts!BU$5:BZ$44,(L25+1)),"")))) -> - | AD25: =IF($L25="X","-",IF(AC25="","-",IF(J25="M",VLOOKUP(AC25,T100Pts!A$5:I$1146,(L25+1)),IF(J25="F",VLOOKUP(AC25,T100Pts!K$5:S$1146,(L25+1)),"")))) -> - | AE25: =IF(OR(X25="X",Z25="X",AB25="X",AD25="X"),"NR",IF(AND(X25="-",Z25="-",AD25="-"),"-",IF(AB25="-",AVERAGE(IF(ISNUMBER(X25),X25),IF(ISNUMBER(Z25),Z25),IF(ISNUMBER(AD25),AD25)),AVERAGE(IF(ISNUMBER(X25),X25),IF(ISNUMBER(Z25),Z25),IF(ISNUMBER(AB25),AB25),IF(ISNUMBER(AD25),AD25))))) -> - | AF25: =IF(NOT(ISNUMBER(AE25)), "-", IF(AE25 < 70, "NA", "A")) -> - | AG25: =AVERAGE(U25,AE25) -> #DIV/0! | AH25: =IF(NOT(ISNUMBER(AG25)), "-", IF(AG25 < 70, "NA", "A")) -> - | AI25: COMISIÓN | AJ25: =IF(OR(B25="TG",B25="GD",B25="GB",B25="CY",B25="CR",B25="TC",B25="MY",B25="CT",B25="TP",B25="TP EC",B25="TT",B25="TT EC",B25="ST",B25="ST EC"),"Oficial",IF(OR(B25="VP",B25="VS",B25="VS EC"),"Vol",IF(B25="","","Subof")))
A26: 13 | I26: =IF(OR(G26="",H26=""),"-",ROUND(G26/(H26^2),0)) -> - | J26: M | K26: =IF(F26>0,DATEDIF(F26,$L$1,"Y"),"-") -> - | L26: =IF(F26="","-",IF(K26<>"",VLOOKUP(K26,T100Pts!CH$4:CI$59,(2)))) -> - | N26: =IF($L26="X","-",IF(M26="","-",IF(J26="M",VLOOKUP(M26,T100Pts!U$5:AC$86,(L26+1)),IF(J26="F",VLOOKUP(M26,T100Pts!AE$5:AM$86,(L26+1)),"")))) -> - | P26: =IF($L26="X","-",IF(O26="","-",IF(J26="M",VLOOKUP(O26,T100Pts!AO$5:AW$126,(L26+1)),IF(J26="F",VLOOKUP(O26,T100Pts!AY$5:BG$126,(L26+1)),"")))) -> - | R26: =IF(OR($L26="X",$L26=6,$L26=7),"-",IF(Q26="","-",IF(J26="M",VLOOKUP(Q26,T100Pts!BI$5:BN$44,(L26+1)),IF(J26="F",VLOOKUP(Q26,T100Pts!BU$5:BZ$44,(L26+1)),"")))) -> - | T26: =IF($L26="X","-",IF(S26="","-",IF(J26="M",VLOOKUP(S26,T100Pts!A$5:I$1146,(L26+1)),IF(J26="F",VLOOKUP(S26,T100Pts!K$5:S$1147,(L26+1)),"")))) -> - | U26: =IF(OR(N26="X",P26="X",R26="X",T26="X"),"NR",IF(AND(N26="-",P26="-",T26="-"),"-",IF(R26="-",AVERAGE(IF(ISNUMBER(N26),N26),IF(ISNUMBER(P26),P26),IF(ISNUMBER(T26),T26)),AVERAGE(IF(ISNUMBER(N26),N26),IF(ISNUMBER(P26),P26),IF(ISNUMBER(R26),R26),IF(ISNUMBER(T26),T26))))) -> - | V26: =IF(NOT(ISNUMBER(U26)), "-", IF(U26 < 70, "NA", "A")) -> - | X26: =IF($L26="X","-",IF(W26="","-",IF(J26="M",VLOOKUP(W26,T100Pts!U$5:AC$86,(L26+1)),IF(J26="F",VLOOKUP(W26,T100Pts!AE$5:AM$86,(L26+1)),"")))) -> - | Z26: =IF($L26="X","-",IF(Y26="","-",IF(J26="M",VLOOKUP(Y26,T100Pts!AO$5:AW$126,(L26+1)),IF(J26="F",VLOOKUP(Y26,T100Pts!AY$5:BG$126,(L26+1)),"")))) -> - | AB26: =IF(OR($L26="X",$L26=6,$L26=7),"-",IF(AA26="","-",IF(J26="M",VLOOKUP(AA26,T100Pts!BI$5:BN$44,(L26+1)),IF(J26="F",VLOOKUP(AA26,T100Pts!BU$5:BZ$44,(L26+1)),"")))) -> - | AD26: =IF($L26="X","-",IF(AC26="","-",IF(J26="M",VLOOKUP(AC26,T100Pts!A$5:I$1146,(L26+1)),IF(J26="F",VLOOKUP(AC26,T100Pts!K$5:S$1146,(L26+1)),"")))) -> - | AE26: =IF(OR(X26="X",Z26="X",AB26="X",AD26="X"),"NR",IF(AND(X26="-",Z26="-",AD26="-"),"-",IF(AB26="-",AVERAGE(IF(ISNUMBER(X26),X26),IF(ISNUMBER(Z26),Z26),IF(ISNUMBER(AD26),AD26)),AVERAGE(IF(ISNUMBER(X26),X26),IF(ISNUMBER(Z26),Z26),IF(ISNUMBER(AB26),AB26),IF(ISNUMBER(AD26),AD26))))) -> - | AF26: =IF(NOT(ISNUMBER(AE26)), "-", IF(AE26 < 70, "NA", "A")) -> - | AG26: =AVERAGE(U26,AE26) -> #DIV/0! | AH26: =IF(NOT(ISNUMBER(AG26)), "-", IF(AG26 < 70, "NA", "A")) -> - | AI26: COMISIÓN | AJ26: =IF(OR(B26="TG",B26="GD",B26="GB",B26="CY",B26="CR",B26="TC",B26="MY",B26="CT",B26="TP",B26="TP EC",B26="TT",B26="TT EC",B26="ST",B26="ST EC"),"Oficial",IF(OR(B26="VP",B26="VS",B26="VS EC"),"Vol",IF(B26="","","Subof")))
A27: 14 | I27: =IF(OR(G27="",H27=""),"-",ROUND(G27/(H27^2),0)) -> - | J27: M | K27: =IF(F27>0,DATEDIF(F27,$L$1,"Y"),"-") -> - | L27: =IF(F27="","-",IF(K27<>"",VLOOKUP(K27,T100Pts!CH$4:CI$59,(2)))) -> - | N27: =IF($L27="X","-",IF(M27="","-",IF(J27="M",VLOOKUP(M27,T100Pts!U$5:AC$86,(L27+1)),IF(J27="F",VLOOKUP(M27,T100Pts!AE$5:AM$86,(L27+1)),"")))) -> - | P27: =IF($L27="X","-",IF(O27="","-",IF(J27="M",VLOOKUP(O27,T100Pts!AO$5:AW$126,(L27+1)),IF(J27="F",VLOOKUP(O27,T100Pts!AY$5:BG$126,(L27+1)),"")))) -> - | R27: =IF(OR($L27="X",$L27=6,$L27=7),"-",IF(Q27="","-",IF(J27="M",VLOOKUP(Q27,T100Pts!BI$5:BN$44,(L27+1)),IF(J27="F",VLOOKUP(Q27,T100Pts!BU$5:BZ$44,(L27+1)),"")))) -> - | T27: =IF($L27="X","-",IF(S27="","-",IF(J27="M",VLOOKUP(S27,T100Pts!A$5:I$1146,(L27+1)),IF(J27="F",VLOOKUP(S27,T100Pts!K$5:S$1147,(L27+1)),"")))) -> - | U27: =IF(OR(N27="X",P27="X",R27="X",T27="X"),"NR",IF(AND(N27="-",P27="-",T27="-"),"-",IF(R27="-",AVERAGE(IF(ISNUMBER(N27),N27),IF(ISNUMBER(P27),P27),IF(ISNUMBER(T27),T27)),AVERAGE(IF(ISNUMBER(N27),N27),IF(ISNUMBER(P27),P27),IF(ISNUMBER(R27),R27),IF(ISNUMBER(T27),T27))))) -> - | V27: =IF(NOT(ISNUMBER(U27)), "-", IF(U27 < 70, "NA", "A")) -> - | X27: =IF($L27="X","-",IF(W27="","-",IF(J27="M",VLOOKUP(W27,T100Pts!U$5:AC$86,(L27+1)),IF(J27="F",VLOOKUP(W27,T100Pts!AE$5:AM$86,(L27+1)),"")))) -> - | Z27: =IF($L27="X","-",IF(Y27="","-",IF(J27="M",VLOOKUP(Y27,T100Pts!AO$5:AW$126,(L27+1)),IF(J27="F",VLOOKUP(Y27,T100Pts!AY$5:BG$126,(L27+1)),"")))) -> - | AB27: =IF(OR($L27="X",$L27=6,$L27=7),"-",IF(AA27="","-",IF(J27="M",VLOOKUP(AA27,T100Pts!BI$5:BN$44,(L27+1)),IF(J27="F",VLOOKUP(AA27,T100Pts!BU$5:BZ$44,(L27+1)),"")))) -> - | AD27: =IF($L27="X","-",IF(AC27="","-",IF(J27="M",VLOOKUP(AC27,T100Pts!A$5:I$1146,(L27+1)),IF(J27="F",VLOOKUP(AC27,T100Pts!K$5:S$1146,(L27+1)),"")))) -> - | AE27: =IF(OR(X27="X",Z27="X",AB27="X",AD27="X"),"NR",IF(AND(X27="-",Z27="-",AD27="-"),"-",IF(AB27="-",AVERAGE(IF(ISNUMBER(X27),X27),IF(ISNUMBER(Z27),Z27),IF(ISNUMBER(AD27),AD27)),AVERAGE(IF(ISNUMBER(X27),X27),IF(ISNUMBER(Z27),Z27),IF(ISNUMBER(AB27),AB27),IF(ISNUMBER(AD27),AD27))))) -> - | AF27: =IF(NOT(ISNUMBER(AE27)), "-", IF(AE27 < 70, "NA", "A")) -> - | AG27: =AVERAGE(U27,AE27) -> #DIV/0! | AH27: =IF(NOT(ISNUMBER(AG27)), "-", IF(AG27 < 70, "NA", "A")) -> - | AJ27: =IF(OR(B27="TG",B27="GD",B27="GB",B27="CY",B27="CR",B27="TC",B27="MY",B27="CT",B27="TP",B27="TP EC",B27="TT",B27="TT EC",B27="ST",B27="ST EC"),"Oficial",IF(OR(B27="VP",B27="VS",B27="VS EC"),"Vol",IF(B27="","","Subof")))
A28: 15 | I28: =IF(OR(G28="",H28=""),"-",ROUND(G28/(H28^2),0)) -> - | J28: M | K28: =IF(F28>0,DATEDIF(F28,$L$1,"Y"),"-") -> - | L28: =IF(F28="","-",IF(K28<>"",VLOOKUP(K28,T100Pts!CH$4:CI$59,(2)))) -> - | N28: =IF($L28="X","-",IF(M28="","-",IF(J28="M",VLOOKUP(M28,T100Pts!U$5:AC$86,(L28+1)),IF(J28="F",VLOOKUP(M28,T100Pts!AE$5:AM$86,(L28+1)),"")))) -> - | P28: =IF($L28="X","-",IF(O28="","-",IF(J28="M",VLOOKUP(O28,T100Pts!AO$5:AW$126,(L28+1)),IF(J28="F",VLOOKUP(O28,T100Pts!AY$5:BG$126,(L28+1)),"")))) -> - | R28: =IF(OR($L28="X",$L28=6,$L28=7),"-",IF(Q28="","-",IF(J28="M",VLOOKUP(Q28,T100Pts!BI$5:BN$44,(L28+1)),IF(J28="F",VLOOKUP(Q28,T100Pts!BU$5:BZ$44,(L28+1)),"")))) -> - | T28: =IF($L28="X","-",IF(S28="","-",IF(J28="M",VLOOKUP(S28,T100Pts!A$5:I$1146,(L28+1)),IF(J28="F",VLOOKUP(S28,T100Pts!K$5:S$1147,(L28+1)),"")))) -> - | U28: =IF(OR(N28="X",P28="X",R28="X",T28="X"),"NR",IF(AND(N28="-",P28="-",T28="-"),"-",IF(R28="-",AVERAGE(IF(ISNUMBER(N28),N28),IF(ISNUMBER(P28),P28),IF(ISNUMBER(T28),T28)),AVERAGE(IF(ISNUMBER(N28),N28),IF(ISNUMBER(P28),P28),IF(ISNUMBER(R28),R28),IF(ISNUMBER(T28),T28))))) -> - | V28: =IF(NOT(ISNUMBER(U28)), "-", IF(U28 < 70, "NA", "A")) -> - | X28: =IF($L28="X","-",IF(W28="","-",IF(J28="M",VLOOKUP(W28,T100Pts!U$5:AC$86,(L28+1)),IF(J28="F",VLOOKUP(W28,T100Pts!AE$5:AM$86,(L28+1)),"")))) -> - | Z28: =IF($L28="X","-",IF(Y28="","-",IF(J28="M",VLOOKUP(Y28,T100Pts!AO$5:AW$126,(L28+1)),IF(J28="F",VLOOKUP(Y28,T100Pts!AY$5:BG$126,(L28+1)),"")))) -> - | AB28: =IF(OR($L28="X",$L28=6,$L28=7),"-",IF(AA28="","-",IF(J28="M",VLOOKUP(AA28,T100Pts!BI$5:BN$44,(L28+1)),IF(J28="F",VLOOKUP(AA28,T100Pts!BU$5:BZ$44,(L28+1)),"")))) -> - | AD28: =IF($L28="X","-",IF(AC28="","-",IF(J28="M",VLOOKUP(AC28,T100Pts!A$5:I$1146,(L28+1)),IF(J28="F",VLOOKUP(AC28,T100Pts!K$5:S$1146,(L28+1)),"")))) -> - | AE28: =IF(OR(X28="X",Z28="X",AB28="X",AD28="X"),"NR",IF(AND(X28="-",Z28="-",AD28="-"),"-",IF(AB28="-",AVERAGE(IF(ISNUMBER(X28),X28),IF(ISNUMBER(Z28),Z28),IF(ISNUMBER(AD28),AD28)),AVERAGE(IF(ISNUMBER(X28),X28),IF(ISNUMBER(Z28),Z28),IF(ISNUMBER(AB28),AB28),IF(ISNUMBER(AD28),AD28))))) -> - | AF28: =IF(NOT(ISNUMBER(AE28)), "-", IF(AE28 < 70, "NA", "A")) -> - | AG28: =AVERAGE(U28,AE28) -> #DIV/0! | AH28: =IF(NOT(ISNUMBER(AG28)), "-", IF(AG28 < 70, "NA", "A")) -> - | AJ28: =IF(OR(B28="TG",B28="GD",B28="GB",B28="CY",B28="CR",B28="TC",B28="MY",B28="CT",B28="TP",B28="TP EC",B28="TT",B28="TT EC",B28="ST",B28="ST EC"),"Oficial",IF(OR(B28="VP",B28="VS",B28="VS EC"),"Vol",IF(B28="","","Subof")))
A29: 16 | I29: =IF(OR(G29="",H29=""),"-",ROUND(G29/(H29^2),0)) -> - | J29: M | K29: =IF(F29>0,DATEDIF(F29,$L$1,"Y"),"-") -> - | L29: =IF(F29="","-",IF(K29<>"",VLOOKUP(K29,T100Pts!CH$4:CI$59,(2)))) -> - | N29: =IF($L29="X","-",IF(M29="","-",IF(J29="M",VLOOKUP(M29,T100Pts!U$5:AC$86,(L29+1)),IF(J29="F",VLOOKUP(M29,T100Pts!AE$5:AM$86,(L29+1)),"")))) -> - | P29: =IF($L29="X","-",IF(O29="","-",IF(J29="M",VLOOKUP(O29,T100Pts!AO$5:AW$126,(L29+1)),IF(J29="F",VLOOKUP(O29,T100Pts!AY$5:BG$126,(L29+1)),"")))) -> - | R29: =IF(OR($L29="X",$L29=6,$L29=7),"-",IF(Q29="","-",IF(J29="M",VLOOKUP(Q29,T100Pts!BI$5:BN$44,(L29+1)),IF(J29="F",VLOOKUP(Q29,T100Pts!BU$5:BZ$44,(L29+1)),"")))) -> - | T29: =IF($L29="X","-",IF(S29="","-",IF(J29="M",VLOOKUP(S29,T100Pts!A$5:I$1146,(L29+1)),IF(J29="F",VLOOKUP(S29,T100Pts!K$5:S$1147,(L29+1)),"")))) -> - | U29: =IF(OR(N29="X",P29="X",R29="X",T29="X"),"NR",IF(AND(N29="-",P29="-",T29="-"),"-",IF(R29="-",AVERAGE(IF(ISNUMBER(N29),N29),IF(ISNUMBER(P29),P29),IF(ISNUMBER(T29),T29)),AVERAGE(IF(ISNUMBER(N29),N29),IF(ISNUMBER(P29),P29),IF(ISNUMBER(R29),R29),IF(ISNUMBER(T29),T29))))) -> - | V29: =IF(NOT(ISNUMBER(U29)), "-", IF(U29 < 70, "NA", "A")) -> - | X29: =IF($L29="X","-",IF(W29="","-",IF(J29="M",VLOOKUP(W29,T100Pts!U$5:AC$86,(L29+1)),IF(J29="F",VLOOKUP(W29,T100Pts!AE$5:AM$86,(L29+1)),"")))) -> - | Z29: =IF($L29="X","-",IF(Y29="","-",IF(J29="M",VLOOKUP(Y29,T100Pts!AO$5:AW$126,(L29+1)),IF(J29="F",VLOOKUP(Y29,T100Pts!AY$5:BG$126,(L29+1)),"")))) -> - | AB29: =IF(OR($L29="X",$L29=6,$L29=7),"-",IF(AA29="","-",IF(J29="M",VLOOKUP(AA29,T100Pts!BI$5:BN$44,(L29+1)),IF(J29="F",VLOOKUP(AA29,T100Pts!BU$5:BZ$44,(L29+1)),"")))) -> - | AD29: =IF($L29="X","-",IF(AC29="","-",IF(J29="M",VLOOKUP(AC29,T100Pts!A$5:I$1146,(L29+1)),IF(J29="F",VLOOKUP(AC29,T100Pts!K$5:S$1146,(L29+1)),"")))) -> - | AE29: =IF(OR(X29="X",Z29="X",AB29="X",AD29="X"),"NR",IF(AND(X29="-",Z29="-",AD29="-"),"-",IF(AB29="-",AVERAGE(IF(ISNUMBER(X29),X29),IF(ISNUMBER(Z29),Z29),IF(ISNUMBER(AD29),AD29)),AVERAGE(IF(ISNUMBER(X29),X29),IF(ISNUMBER(Z29),Z29),IF(ISNUMBER(AB29),AB29),IF(ISNUMBER(AD29),AD29))))) -> - | AF29: =IF(NOT(ISNUMBER(AE29)), "-", IF(AE29 < 70, "NA", "A")) -> - | AG29: =AVERAGE(U29,AE29) -> #DIV/0! | AH29: =IF(NOT(ISNUMBER(AG29)), "-", IF(AG29 < 70, "NA", "A")) -> - | AJ29: =IF(OR(B29="TG",B29="GD",B29="GB",B29="CY",B29="CR",B29="TC",B29="MY",B29="CT",B29="TP",B29="TP EC",B29="TT",B29="TT EC",B29="ST",B29="ST EC"),"Oficial",IF(OR(B29="VP",B29="VS",B29="VS EC"),"Vol",IF(B29="","","Subof")))
A30: 17 | I30: =IF(OR(G30="",H30=""),"-",ROUND(G30/(H30^2),0)) -> - | J30: M | K30: =IF(F30>0,DATEDIF(F30,$L$1,"Y"),"-") -> - | L30: =IF(F30="","-",IF(K30<>"",VLOOKUP(K30,T100Pts!CH$4:CI$59,(2)))) -> - | N30: =IF($L30="X","-",IF(M30="","-",IF(J30="M",VLOOKUP(M30,T100Pts!U$5:AC$86,(L30+1)),IF(J30="F",VLOOKUP(M30,T100Pts!AE$5:AM$86,(L30+1)),"")))) -> - | P30: =IF($L30="X","-",IF(O30="","-",IF(J30="M",VLOOKUP(O30,T100Pts!AO$5:AW$126,(L30+1)),IF(J30="F",VLOOKUP(O30,T100Pts!AY$5:BG$126,(L30+1)),"")))) -> - | R30: =IF(OR($L30="X",$L30=6,$L30=7),"-",IF(Q30="","-",IF(J30="M",VLOOKUP(Q30,T100Pts!BI$5:BN$44,(L30+1)),IF(J30="F",VLOOKUP(Q30,T100Pts!BU$5:BZ$44,(L30+1)),"")))) -> - | T30: =IF($L30="X","-",IF(S30="","-",IF(J30="M",VLOOKUP(S30,T100Pts!A$5:I$1146,(L30+1)),IF(J30="F",VLOOKUP(S30,T100Pts!K$5:S$1147,(L30+1)),"")))) -> - | U30: =IF(OR(N30="X",P30="X",R30="X",T30="X"),"NR",IF(AND(N30="-",P30="-",T30="-"),"-",IF(R30="-",AVERAGE(IF(ISNUMBER(N30),N30),IF(ISNUMBER(P30),P30),IF(ISNUMBER(T30),T30)),AVERAGE(IF(ISNUMBER(N30),N30),IF(ISNUMBER(P30),P30),IF(ISNUMBER(R30),R30),IF(ISNUMBER(T30),T30))))) -> - | V30: =IF(NOT(ISNUMBER(U30)), "-", IF(U30 < 70, "NA", "A")) -> - | X30: =IF($L30="X","-",IF(W30="","-",IF(J30="M",VLOOKUP(W30,T100Pts!U$5:AC$86,(L30+1)),IF(J30="F",VLOOKUP(W30,T100Pts!AE$5:AM$86,(L30+1)),"")))) -> - | Z30: =IF($L30="X","-",IF(Y30="","-",IF(J30="M",VLOOKUP(Y30,T100Pts!AO$5:AW$126,(L30+1)),IF(J30="F",VLOOKUP(Y30,T100Pts!AY$5:BG$126,(L30+1)),"")))) -> - | AB30: =IF(OR($L30="X",$L30=6,$L30=7),"-",IF(AA30="","-",IF(J30="M",VLOOKUP(AA30,T100Pts!BI$5:BN$44,(L30+1)),IF(J30="F",VLOOKUP(AA30,T100Pts!BU$5:BZ$44,(L30+1)),"")))) -> - | AD30: =IF($L30="X","-",IF(AC30="","-",IF(J30="M",VLOOKUP(AC30,T100Pts!A$5:I$1146,(L30+1)),IF(J30="F",VLOOKUP(AC30,T100Pts!K$5:S$1146,(L30+1)),"")))) -> - | AE30: =IF(OR(X30="X",Z30="X",AB30="X",AD30="X"),"NR",IF(AND(X30="-",Z30="-",AD30="-"),"-",IF(AB30="-",AVERAGE(IF(ISNUMBER(X30),X30),IF(ISNUMBER(Z30),Z30),IF(ISNUMBER(AD30),AD30)),AVERAGE(IF(ISNUMBER(X30),X30),IF(ISNUMBER(Z30),Z30),IF(ISNUMBER(AB30),AB30),IF(ISNUMBER(AD30),AD30))))) -> - | AF30: =IF(NOT(ISNUMBER(AE30)), "-", IF(AE30 < 70, "NA", "A")) -> - | AG30: =AVERAGE(U30,AE30) -> #DIV/0! | AH30: =IF(NOT(ISNUMBER(AG30)), "-", IF(AG30 < 70, "NA", "A")) -> - | AI30: GENERO | AJ30: =IF(OR(B30="TG",B30="GD",B30="GB",B30="CY",B30="CR",B30="TC",B30="MY",B30="CT",B30="TP",B30="TP EC",B30="TT",B30="TT EC",B30="ST",B30="ST EC"),"Oficial",IF(OR(B30="VP",B30="VS",B30="VS EC"),"Vol",IF(B30="","","Subof")))
A31: 18 | I31: =IF(OR(G31="",H31=""),"-",ROUND(G31/(H31^2),0)) -> - | J31: M | K31: =IF(F31>0,DATEDIF(F31,$L$1,"Y"),"-") -> - | L31: =IF(F31="","-",IF(K31<>"",VLOOKUP(K31,T100Pts!CH$4:CI$59,(2)))) -> - | N31: =IF($L31="X","-",IF(M31="","-",IF(J31="M",VLOOKUP(M31,T100Pts!U$5:AC$86,(L31+1)),IF(J31="F",VLOOKUP(M31,T100Pts!AE$5:AM$86,(L31+1)),"")))) -> - | P31: =IF($L31="X","-",IF(O31="","-",IF(J31="M",VLOOKUP(O31,T100Pts!AO$5:AW$126,(L31+1)),IF(J31="F",VLOOKUP(O31,T100Pts!AY$5:BG$126,(L31+1)),"")))) -> - | R31: =IF(OR($L31="X",$L31=6,$L31=7),"-",IF(Q31="","-",IF(J31="M",VLOOKUP(Q31,T100Pts!BI$5:BN$44,(L31+1)),IF(J31="F",VLOOKUP(Q31,T100Pts!BU$5:BZ$44,(L31+1)),"")))) -> - | T31: =IF($L31="X","-",IF(S31="","-",IF(J31="M",VLOOKUP(S31,T100Pts!A$5:I$1146,(L31+1)),IF(J31="F",VLOOKUP(S31,T100Pts!K$5:S$1147,(L31+1)),"")))) -> - | U31: =IF(OR(N31="X",P31="X",R31="X",T31="X"),"NR",IF(AND(N31="-",P31="-",T31="-"),"-",IF(R31="-",AVERAGE(IF(ISNUMBER(N31),N31),IF(ISNUMBER(P31),P31),IF(ISNUMBER(T31),T31)),AVERAGE(IF(ISNUMBER(N31),N31),IF(ISNUMBER(P31),P31),IF(ISNUMBER(R31),R31),IF(ISNUMBER(T31),T31))))) -> - | V31: =IF(NOT(ISNUMBER(U31)), "-", IF(U31 < 70, "NA", "A")) -> - | X31: =IF($L31="X","-",IF(W31="","-",IF(J31="M",VLOOKUP(W31,T100Pts!U$5:AC$86,(L31+1)),IF(J31="F",VLOOKUP(W31,T100Pts!AE$5:AM$86,(L31+1)),"")))) -> - | Z31: =IF($L31="X","-",IF(Y31="","-",IF(J31="M",VLOOKUP(Y31,T100Pts!AO$5:AW$126,(L31+1)),IF(J31="F",VLOOKUP(Y31,T100Pts!AY$5:BG$126,(L31+1)),"")))) -> - | AB31: =IF(OR($L31="X",$L31=6,$L31=7),"-",IF(AA31="","-",IF(J31="M",VLOOKUP(AA31,T100Pts!BI$5:BN$44,(L31+1)),IF(J31="F",VLOOKUP(AA31,T100Pts!BU$5:BZ$44,(L31+1)),"")))) -> - | AD31: =IF($L31="X","-",IF(AC31="","-",IF(J31="M",VLOOKUP(AC31,T100Pts!A$5:I$1146,(L31+1)),IF(J31="F",VLOOKUP(AC31,T100Pts!K$5:S$1146,(L31+1)),"")))) -> - | AE31: =IF(OR(X31="X",Z31="X",AB31="X",AD31="X"),"NR",IF(AND(X31="-",Z31="-",AD31="-"),"-",IF(AB31="-",AVERAGE(IF(ISNUMBER(X31),X31),IF(ISNUMBER(Z31),Z31),IF(ISNUMBER(AD31),AD31)),AVERAGE(IF(ISNUMBER(X31),X31),IF(ISNUMBER(Z31),Z31),IF(ISNUMBER(AB31),AB31),IF(ISNUMBER(AD31),AD31))))) -> - | AF31: =IF(NOT(ISNUMBER(AE31)), "-", IF(AE31 < 70, "NA", "A")) -> - | AG31: =AVERAGE(U31,AE31) -> #DIV/0! | AH31: =IF(NOT(ISNUMBER(AG31)), "-", IF(AG31 < 70, "NA", "A")) -> - | AI31: PARTE DE ENFERMO RODILLA | AJ31: =IF(OR(B31="TG",B31="GD",B31="GB",B31="CY",B31="CR",B31="TC",B31="MY",B31="CT",B31="TP",B31="TP EC",B31="TT",B31="TT EC",B31="ST",B31="ST EC"),"Oficial",IF(OR(B31="VP",B31="VS",B31="VS EC"),"Vol",IF(B31="","","Subof")))
A32: 19 | I32: =IF(OR(G32="",H32=""),"-",ROUND(G32/(H32^2),0)) -> - | J32: M | K32: =IF(F32>0,DATEDIF(F32,$L$1,"Y"),"-") -> - | L32: =IF(F32="","-",IF(K32<>"",VLOOKUP(K32,T100Pts!CH$4:CI$59,(2)))) -> - | N32: =IF($L32="X","-",IF(M32="","-",IF(J32="M",VLOOKUP(M32,T100Pts!U$5:AC$86,(L32+1)),IF(J32="F",VLOOKUP(M32,T100Pts!AE$5:AM$86,(L32+1)),"")))) -> - | P32: =IF($L32="X","-",IF(O32="","-",IF(J32="M",VLOOKUP(O32,T100Pts!AO$5:AW$126,(L32+1)),IF(J32="F",VLOOKUP(O32,T100Pts!AY$5:BG$126,(L32+1)),"")))) -> - | R32: =IF(OR($L32="X",$L32=6,$L32=7),"-",IF(Q32="","-",IF(J32="M",VLOOKUP(Q32,T100Pts!BI$5:BN$44,(L32+1)),IF(J32="F",VLOOKUP(Q32,T100Pts!BU$5:BZ$44,(L32+1)),"")))) -> - | T32: =IF($L32="X","-",IF(S32="","-",IF(J32="M",VLOOKUP(S32,T100Pts!A$5:I$1146,(L32+1)),IF(J32="F",VLOOKUP(S32,T100Pts!K$5:S$1147,(L32+1)),"")))) -> - | U32: =IF(OR(N32="X",P32="X",R32="X",T32="X"),"NR",IF(AND(N32="-",P32="-",T32="-"),"-",IF(R32="-",AVERAGE(IF(ISNUMBER(N32),N32),IF(ISNUMBER(P32),P32),IF(ISNUMBER(T32),T32)),AVERAGE(IF(ISNUMBER(N32),N32),IF(ISNUMBER(P32),P32),IF(ISNUMBER(R32),R32),IF(ISNUMBER(T32),T32))))) -> - | V32: =IF(NOT(ISNUMBER(U32)), "-", IF(U32 < 70, "NA", "A")) -> - | X32: =IF($L32="X","-",IF(W32="","-",IF(J32="M",VLOOKUP(W32,T100Pts!U$5:AC$86,(L32+1)),IF(J32="F",VLOOKUP(W32,T100Pts!AE$5:AM$86,(L32+1)),"")))) -> - | Z32: =IF($L32="X","-",IF(Y32="","-",IF(J32="M",VLOOKUP(Y32,T100Pts!AO$5:AW$126,(L32+1)),IF(J32="F",VLOOKUP(Y32,T100Pts!AY$5:BG$126,(L32+1)),"")))) -> - | AB32: =IF(OR($L32="X",$L32=6,$L32=7),"-",IF(AA32="","-",IF(J32="M",VLOOKUP(AA32,T100Pts!BI$5:BN$44,(L32+1)),IF(J32="F",VLOOKUP(AA32,T100Pts!BU$5:BZ$44,(L32+1)),"")))) -> - | AD32: =IF($L32="X","-",IF(AC32="","-",IF(J32="M",VLOOKUP(AC32,T100Pts!A$5:I$1146,(L32+1)),IF(J32="F",VLOOKUP(AC32,T100Pts!K$5:S$1146,(L32+1)),"")))) -> - | AE32: =IF(OR(X32="X",Z32="X",AB32="X",AD32="X"),"NR",IF(AND(X32="-",Z32="-",AD32="-"),"-",IF(AB32="-",AVERAGE(IF(ISNUMBER(X32),X32),IF(ISNUMBER(Z32),Z32),IF(ISNUMBER(AD32),AD32)),AVERAGE(IF(ISNUMBER(X32),X32),IF(ISNUMBER(Z32),Z32),IF(ISNUMBER(AB32),AB32),IF(ISNUMBER(AD32),AD32))))) -> - | AF32: =IF(NOT(ISNUMBER(AE32)), "-", IF(AE32 < 70, "NA", "A")) -> - | AG32: =AVERAGE(U32,AE32) -> #DIV/0! | AH32: =IF(NOT(ISNUMBER(AG32)), "-", IF(AG32 < 70, "NA", "A")) -> - | AI32: SIN ANEXO 27 1ER SEM | AJ32: =IF(OR(B32="TG",B32="GD",B32="GB",B32="CY",B32="CR",B32="TC",B32="MY",B32="CT",B32="TP",B32="TP EC",B32="TT",B32="TT EC",B32="ST",B32="ST EC"),"Oficial",IF(OR(B32="VP",B32="VS",B32="VS EC"),"Vol",IF(B32="","","Subof")))
A33: 20 | I33: =IF(OR(G33="",H33=""),"-",ROUND(G33/(H33^2),0)) -> - | J33: M | K33: =IF(F33>0,DATEDIF(F33,$L$1,"Y"),"-") -> - | L33: =IF(F33="","-",IF(K33<>"",VLOOKUP(K33,T100Pts!CH$4:CI$59,(2)))) -> - | N33: =IF($L33="X","-",IF(M33="","-",IF(J33="M",VLOOKUP(M33,T100Pts!U$5:AC$86,(L33+1)),IF(J33="F",VLOOKUP(M33,T100Pts!AE$5:AM$86,(L33+1)),"")))) -> - | P33: =IF($L33="X","-",IF(O33="","-",IF(J33="M",VLOOKUP(O33,T100Pts!AO$5:AW$126,(L33+1)),IF(J33="F",VLOOKUP(O33,T100Pts!AY$5:BG$126,(L33+1)),"")))) -> - | R33: =IF(OR($L33="X",$L33=6,$L33=7),"-",IF(Q33="","-",IF(J33="M",VLOOKUP(Q33,T100Pts!BI$5:BN$44,(L33+1)),IF(J33="F",VLOOKUP(Q33,T100Pts!BU$5:BZ$44,(L33+1)),"")))) -> - | T33: =IF($L33="X","-",IF(S33="","-",IF(J33="M",VLOOKUP(S33,T100Pts!A$5:I$1146,(L33+1)),IF(J33="F",VLOOKUP(S33,T100Pts!K$5:S$1147,(L33+1)),"")))) -> - | U33: =IF(OR(N33="X",P33="X",R33="X",T33="X"),"NR",IF(AND(N33="-",P33="-",T33="-"),"-",IF(R33="-",AVERAGE(IF(ISNUMBER(N33),N33),IF(ISNUMBER(P33),P33),IF(ISNUMBER(T33),T33)),AVERAGE(IF(ISNUMBER(N33),N33),IF(ISNUMBER(P33),P33),IF(ISNUMBER(R33),R33),IF(ISNUMBER(T33),T33))))) -> - | V33: =IF(NOT(ISNUMBER(U33)), "-", IF(U33 < 70, "NA", "A")) -> - | X33: =IF($L33="X","-",IF(W33="","-",IF(J33="M",VLOOKUP(W33,T100Pts!U$5:AC$86,(L33+1)),IF(J33="F",VLOOKUP(W33,T100Pts!AE$5:AM$86,(L33+1)),"")))) -> - | Z33: =IF($L33="X","-",IF(Y33="","-",IF(J33="M",VLOOKUP(Y33,T100Pts!AO$5:AW$126,(L33+1)),IF(J33="F",VLOOKUP(Y33,T100Pts!AY$5:BG$126,(L33+1)),"")))) -> - | AB33: =IF(OR($L33="X",$L33=6,$L33=7),"-",IF(AA33="","-",IF(J33="M",VLOOKUP(AA33,T100Pts!BI$5:BN$44,(L33+1)),IF(J33="F",VLOOKUP(AA33,T100Pts!BU$5:BZ$44,(L33+1)),"")))) -> - | AD33: =IF($L33="X","-",IF(AC33="","-",IF(J33="M",VLOOKUP(AC33,T100Pts!A$5:I$1146,(L33+1)),IF(J33="F",VLOOKUP(AC33,T100Pts!K$5:S$1146,(L33+1)),"")))) -> - | AE33: =IF(OR(X33="X",Z33="X",AB33="X",AD33="X"),"NR",IF(AND(X33="-",Z33="-",AD33="-"),"-",IF(AB33="-",AVERAGE(IF(ISNUMBER(X33),X33),IF(ISNUMBER(Z33),Z33),IF(ISNUMBER(AD33),AD33)),AVERAGE(IF(ISNUMBER(X33),X33),IF(ISNUMBER(Z33),Z33),IF(ISNUMBER(AB33),AB33),IF(ISNUMBER(AD33),AD33))))) -> - | AF33: =IF(NOT(ISNUMBER(AE33)), "-", IF(AE33 < 70, "NA", "A")) -> - | AG33: =AVERAGE(U33,AE33) -> #DIV/0! | AH33: =IF(NOT(ISNUMBER(AG33)), "-", IF(AG33 < 70, "NA", "A")) -> - | AJ33: =IF(OR(B33="TG",B33="GD",B33="GB",B33="CY",B33="CR",B33="TC",B33="MY",B33="CT",B33="TP",B33="TP EC",B33="TT",B33="TT EC",B33="ST",B33="ST EC"),"Oficial",IF(OR(B33="VP",B33="VS",B33="VS EC"),"Vol",IF(B33="","","Subof")))
A34: 21 | I34: =IF(OR(G34="",H34=""),"-",ROUND(G34/(H34^2),0)) -> - | J34: M | K34: =IF(F34>0,DATEDIF(F34,$L$1,"Y"),"-") -> - | L34: =IF(F34="","-",IF(K34<>"",VLOOKUP(K34,T100Pts!CH$4:CI$59,(2)))) -> - | N34: =IF($L34="X","-",IF(M34="","-",IF(J34="M",VLOOKUP(M34,T100Pts!U$5:AC$86,(L34+1)),IF(J34="F",VLOOKUP(M34,T100Pts!AE$5:AM$86,(L34+1)),"")))) -> - | P34: =IF($L34="X","-",IF(O34="","-",IF(J34="M",VLOOKUP(O34,T100Pts!AO$5:AW$126,(L34+1)),IF(J34="F",VLOOKUP(O34,T100Pts!AY$5:BG$126,(L34+1)),"")))) -> - | R34: =IF(OR($L34="X",$L34=6,$L34=7),"-",IF(Q34="","-",IF(J34="M",VLOOKUP(Q34,T100Pts!BI$5:BN$44,(L34+1)),IF(J34="F",VLOOKUP(Q34,T100Pts!BU$5:BZ$44,(L34+1)),"")))) -> - | T34: =IF($L34="X","-",IF(S34="","-",IF(J34="M",VLOOKUP(S34,T100Pts!A$5:I$1146,(L34+1)),IF(J34="F",VLOOKUP(S34,T100Pts!K$5:S$1147,(L34+1)),"")))) -> - | U34: =IF(OR(N34="X",P34="X",R34="X",T34="X"),"NR",IF(AND(N34="-",P34="-",T34="-"),"-",IF(R34="-",AVERAGE(IF(ISNUMBER(N34),N34),IF(ISNUMBER(P34),P34),IF(ISNUMBER(T34),T34)),AVERAGE(IF(ISNUMBER(N34),N34),IF(ISNUMBER(P34),P34),IF(ISNUMBER(R34),R34),IF(ISNUMBER(T34),T34))))) -> - | V34: =IF(NOT(ISNUMBER(U34)), "-", IF(U34 < 70, "NA", "A")) -> - | X34: =IF($L34="X","-",IF(W34="","-",IF(J34="M",VLOOKUP(W34,T100Pts!U$5:AC$86,(L34+1)),IF(J34="F",VLOOKUP(W34,T100Pts!AE$5:AM$86,(L34+1)),"")))) -> - | Z34: =IF($L34="X","-",IF(Y34="","-",IF(J34="M",VLOOKUP(Y34,T100Pts!AO$5:AW$126,(L34+1)),IF(J34="F",VLOOKUP(Y34,T100Pts!AY$5:BG$126,(L34+1)),"")))) -> - | AB34: =IF(OR($L34="X",$L34=6,$L34=7),"-",IF(AA34="","-",IF(J34="M",VLOOKUP(AA34,T100Pts!BI$5:BN$44,(L34+1)),IF(J34="F",VLOOKUP(AA34,T100Pts!BU$5:BZ$44,(L34+1)),"")))) -> - | AD34: =IF($L34="X","-",IF(AC34="","-",IF(J34="M",VLOOKUP(AC34,T100Pts!A$5:I$1146,(L34+1)),IF(J34="F",VLOOKUP(AC34,T100Pts!K$5:S$1146,(L34+1)),"")))) -> - | AE34: =IF(OR(X34="X",Z34="X",AB34="X",AD34="X"),"NR",IF(AND(X34="-",Z34="-",AD34="-"),"-",IF(AB34="-",AVERAGE(IF(ISNUMBER(X34),X34),IF(ISNUMBER(Z34),Z34),IF(ISNUMBER(AD34),AD34)),AVERAGE(IF(ISNUMBER(X34),X34),IF(ISNUMBER(Z34),Z34),IF(ISNUMBER(AB34),AB34),IF(ISNUMBER(AD34),AD34))))) -> - | AF34: =IF(NOT(ISNUMBER(AE34)), "-", IF(AE34 < 70, "NA", "A")) -> - | AG34: =AVERAGE(U34,AE34) -> #DIV/0! | AH34: =IF(NOT(ISNUMBER(AG34)), "-", IF(AG34 < 70, "NA", "A")) -> - | AJ34: =IF(OR(B34="TG",B34="GD",B34="GB",B34="CY",B34="CR",B34="TC",B34="MY",B34="CT",B34="TP",B34="TP EC",B34="TT",B34="TT EC",B34="ST",B34="ST EC"),"Oficial",IF(OR(B34="VP",B34="VS",B34="VS EC"),"Vol",IF(B34="","","Subof")))
A35: 22 | I35: =IF(OR(G35="",H35=""),"-",ROUND(G35/(H35^2),0)) -> - | J35: M | K35: =IF(F35>0,DATEDIF(F35,$L$1,"Y"),"-") -> - | L35: =IF(F35="","-",IF(K35<>"",VLOOKUP(K35,T100Pts!CH$4:CI$59,(2)))) -> - | N35: =IF($L35="X","-",IF(M35="","-",IF(J35="M",VLOOKUP(M35,T100Pts!U$5:AC$86,(L35+1)),IF(J35="F",VLOOKUP(M35,T100Pts!AE$5:AM$86,(L35+1)),"")))) -> - | P35: =IF($L35="X","-",IF(O35="","-",IF(J35="M",VLOOKUP(O35,T100Pts!AO$5:AW$126,(L35+1)),IF(J35="F",VLOOKUP(O35,T100Pts!AY$5:BG$126,(L35+1)),"")))) -> - | R35: =IF(OR($L35="X",$L35=6,$L35=7),"-",IF(Q35="","-",IF(J35="M",VLOOKUP(Q35,T100Pts!BI$5:BN$44,(L35+1)),IF(J35="F",VLOOKUP(Q35,T100Pts!BU$5:BZ$44,(L35+1)),"")))) -> - | T35: =IF($L35="X","-",IF(S35="","-",IF(J35="M",VLOOKUP(S35,T100Pts!A$5:I$1146,(L35+1)),IF(J35="F",VLOOKUP(S35,T100Pts!K$5:S$1147,(L35+1)),"")))) -> - | U35: =IF(OR(N35="X",P35="X",R35="X",T35="X"),"NR",IF(AND(N35="-",P35="-",T35="-"),"-",IF(R35="-",AVERAGE(IF(ISNUMBER(N35),N35),IF(ISNUMBER(P35),P35),IF(ISNUMBER(T35),T35)),AVERAGE(IF(ISNUMBER(N35),N35),IF(ISNUMBER(P35),P35),IF(ISNUMBER(R35),R35),IF(ISNUMBER(T35),T35))))) -> - | V35: =IF(NOT(ISNUMBER(U35)), "-", IF(U35 < 70, "NA", "A")) -> - | X35: =IF($L35="X","-",IF(W35="","-",IF(J35="M",VLOOKUP(W35,T100Pts!U$5:AC$86,(L35+1)),IF(J35="F",VLOOKUP(W35,T100Pts!AE$5:AM$86,(L35+1)),"")))) -> - | Z35: =IF($L35="X","-",IF(Y35="","-",IF(J35="M",VLOOKUP(Y35,T100Pts!AO$5:AW$126,(L35+1)),IF(J35="F",VLOOKUP(Y35,T100Pts!AY$5:BG$126,(L35+1)),"")))) -> - | AB35: =IF(OR($L35="X",$L35=6,$L35=7),"-",IF(AA35="","-",IF(J35="M",VLOOKUP(AA35,T100Pts!BI$5:BN$44,(L35+1)),IF(J35="F",VLOOKUP(AA35,T100Pts!BU$5:BZ$44,(L35+1)),"")))) -> - | AD35: =IF($L35="X","-",IF(AC35="","-",IF(J35="M",VLOOKUP(AC35,T100Pts!A$5:I$1146,(L35+1)),IF(J35="F",VLOOKUP(AC35,T100Pts!K$5:S$1146,(L35+1)),"")))) -> - | AE35: =IF(OR(X35="X",Z35="X",AB35="X",AD35="X"),"NR",IF(AND(X35="-",Z35="-",AD35="-"),"-",IF(AB35="-",AVERAGE(IF(ISNUMBER(X35),X35),IF(ISNUMBER(Z35),Z35),IF(ISNUMBER(AD35),AD35)),AVERAGE(IF(ISNUMBER(X35),X35),IF(ISNUMBER(Z35),Z35),IF(ISNUMBER(AB35),AB35),IF(ISNUMBER(AD35),AD35))))) -> - | AF35: =IF(NOT(ISNUMBER(AE35)), "-", IF(AE35 < 70, "NA", "A")) -> - | AG35: =AVERAGE(U35,AE35) -> #DIV/0! | AH35: =IF(NOT(ISNUMBER(AG35)), "-", IF(AG35 < 70, "NA", "A")) -> - | AI35: DAF CIE: I 10 | AJ35: =IF(OR(B35="TG",B35="GD",B35="GB",B35="CY",B35="CR",B35="TC",B35="MY",B35="CT",B35="TP",B35="TP EC",B35="TT",B35="TT EC",B35="ST",B35="ST EC"),"Oficial",IF(OR(B35="VP",B35="VS",B35="VS EC"),"Vol",IF(B35="","","Subof")))
A36: 23 | I36: =IF(OR(G36="",H36=""),"-",ROUND(G36/(H36^2),0)) -> - | J36: M | K36: =IF(F36>0,DATEDIF(F36,$L$1,"Y"),"-") -> - | L36: =IF(F36="","-",IF(K36<>"",VLOOKUP(K36,T100Pts!CH$4:CI$59,(2)))) -> - | N36: =IF($L36="X","-",IF(M36="","-",IF(J36="M",VLOOKUP(M36,T100Pts!U$5:AC$86,(L36+1)),IF(J36="F",VLOOKUP(M36,T100Pts!AE$5:AM$86,(L36+1)),"")))) -> - | P36: =IF($L36="X","-",IF(O36="","-",IF(J36="M",VLOOKUP(O36,T100Pts!AO$5:AW$126,(L36+1)),IF(J36="F",VLOOKUP(O36,T100Pts!AY$5:BG$126,(L36+1)),"")))) -> - | R36: =IF(OR($L36="X",$L36=6,$L36=7),"-",IF(Q36="","-",IF(J36="M",VLOOKUP(Q36,T100Pts!BI$5:BN$44,(L36+1)),IF(J36="F",VLOOKUP(Q36,T100Pts!BU$5:BZ$44,(L36+1)),"")))) -> - | T36: =IF($L36="X","-",IF(S36="","-",IF(J36="M",VLOOKUP(S36,T100Pts!A$5:I$1146,(L36+1)),IF(J36="F",VLOOKUP(S36,T100Pts!K$5:S$1147,(L36+1)),"")))) -> - | U36: =IF(OR(N36="X",P36="X",R36="X",T36="X"),"NR",IF(AND(N36="-",P36="-",T36="-"),"-",IF(R36="-",AVERAGE(IF(ISNUMBER(N36),N36),IF(ISNUMBER(P36),P36),IF(ISNUMBER(T36),T36)),AVERAGE(IF(ISNUMBER(N36),N36),IF(ISNUMBER(P36),P36),IF(ISNUMBER(R36),R36),IF(ISNUMBER(T36),T36))))) -> - | V36: =IF(NOT(ISNUMBER(U36)), "-", IF(U36 < 70, "NA", "A")) -> - | X36: =IF($L36="X","-",IF(W36="","-",IF(J36="M",VLOOKUP(W36,T100Pts!U$5:AC$86,(L36+1)),IF(J36="F",VLOOKUP(W36,T100Pts!AE$5:AM$86,(L36+1)),"")))) -> - | Z36: =IF($L36="X","-",IF(Y36="","-",IF(J36="M",VLOOKUP(Y36,T100Pts!AO$5:AW$126,(L36+1)),IF(J36="F",VLOOKUP(Y36,T100Pts!AY$5:BG$126,(L36+1)),"")))) -> - | AB36: =IF(OR($L36="X",$L36=6,$L36=7),"-",IF(AA36="","-",IF(J36="M",VLOOKUP(AA36,T100Pts!BI$5:BN$44,(L36+1)),IF(J36="F",VLOOKUP(AA36,T100Pts!BU$5:BZ$44,(L36+1)),"")))) -> - | AD36: =IF($L36="X","-",IF(AC36="","-",IF(J36="M",VLOOKUP(AC36,T100Pts!A$5:I$1146,(L36+1)),IF(J36="F",VLOOKUP(AC36,T100Pts!K$5:S$1146,(L36+1)),"")))) -> - | AE36: =IF(OR(X36="X",Z36="X",AB36="X",AD36="X"),"NR",IF(AND(X36="-",Z36="-",AD36="-"),"-",IF(AB36="-",AVERAGE(IF(ISNUMBER(X36),X36),IF(ISNUMBER(Z36),Z36),IF(ISNUMBER(AD36),AD36)),AVERAGE(IF(ISNUMBER(X36),X36),IF(ISNUMBER(Z36),Z36),IF(ISNUMBER(AB36),AB36),IF(ISNUMBER(AD36),AD36))))) -> - | AF36: =IF(NOT(ISNUMBER(AE36)), "-", IF(AE36 < 70, "NA", "A")) -> - | AG36: =AVERAGE(U36,AE36) -> #DIV/0! | AH36: =IF(NOT(ISNUMBER(AG36)), "-", IF(AG36 < 70, "NA", "A")) -> - | AJ36: =IF(OR(B36="TG",B36="GD",B36="GB",B36="CY",B36="CR",B36="TC",B36="MY",B36="CT",B36="TP",B36="TP EC",B36="TT",B36="TT EC",B36="ST",B36="ST EC"),"Oficial",IF(OR(B36="VP",B36="VS",B36="VS EC"),"Vol",IF(B36="","","Subof")))
